Workbook

Sheet Resumo_DPO 
AE2: 0.5 | AF2: 0.6 | AG2: 0.7
B4: DISTRIBUIDOR XXXXX | G4: H 2025 | M4: Almacén | P4: Entrega | S4: MKTP
B6: PILARES | E6: META | G6: Enviado | I6: 2025 | K6: Disp.% | M6: DIST | N6: 3PL | P6: DIST | Q6: 3PL
B8: Pilar Seguridad | C8: =VLOOKUP(I8,#REF!,4) -> #REF! | E8: 0.73 | I8: =+'Seguridad OK'!$R$2 -> 0 | K8: =ABS(I8-G8) -> 0 | M8: =+'Seguridad OK'!M2 -> 0 | N8: 0.7 | P8: =+'Seguridad OK'!P2 -> 0 | Q8: 0.57 | V8: 2
B9: Pilar Gente | C9: =VLOOKUP(I9,#REF!,4) -> #REF! | E9: 0.57 | I9: =+'Gente OK'!$R$2 -> 0 | K9: =ABS(I9-G9) -> 0 | M9: =+'Gente OK'!M2 -> 0 | N9: 0.7 | P9: =+'Gente OK'!P2 -> 0 | Q9: 0.57
B10: Pilar Gestión | C10: =VLOOKUP(I10,#REF!,4) -> #REF! | E10: 0.57 | I10: =+'Gestión OK'!$R$2 -> 0 | K10: =ABS(I10-G10) -> 0 | M10: =+'Gestión OK'!M2 -> 0 | N10: 0.7 | P10: =+'Gestión OK'!P2 -> 0 | Q10: 0.57 | AE10: Certificado
B11: Pilar Entrega | C11: =VLOOKUP(I11,#REF!,4) -> #REF! | E11: 0.64 | I11: =+'Entrega OK'!$R$2 -> 0 | K11: =ABS(I11-G11) -> 0 | M11: =+'Entrega OK'!M2 -> N/A | N11: 0.7 | P11: =+'Entrega OK'!P2 -> 0 | Q11: 0.57
B12: Pilar Flota | C12: =VLOOKUP(I12,#REF!,4) -> #REF! | E12: 0.64 | I12: =+'Flota OK'!$R$2 -> 0 | K12: =ABS(I12-G12) -> 0 | M12: =+'Flota OK'!M2 -> 0 | N12: 0.7 | P12: =+'Flota OK'!P2 -> 0 | Q12: 0.57
B13: Pilar Almacén | C13: =VLOOKUP(I13,#REF!,4) -> #REF! | E13: 0.64 | I13: =+'Almacén OK'!$O$2 -> 0 | K13: =ABS(I13-G13) -> 0 | M13: =+'Almacén OK'!L2 -> 0 | N13: 0.7 | P13: N/A | Q13: 0.57 | AE13: =IF(AND(I8<$AG$2,I8>=AF2,I9>=$AF$2),"Certificado","Outro") -> Outro
B14: Pilar Planeamiento | C14: =VLOOKUP(I14,#REF!,4) -> #REF! | E14: 0.64 | I14: =+'Planeamiento OK'!$R$2 -> 0 | K14: =ABS(I14-G14) -> 0 | M14: =+'Planeamiento OK'!M2 -> 0 | N14: 0.7 | P14: =+'Planeamiento OK'!P2 -> 0 | Q14: 0.57
B16: TOTAL | E16: 0.64 | G16: =AVERAGE(G8:G14) -> #DIV/0! | I16: =AVERAGE(I8:I14) -> 0 | K16: =AVERAGE(K8:K14) -> 0 | M16: =IFERROR(AVERAGE(M8:M14),"") -> 0 | N16: =IFERROR(AVERAGE(N8:N14),"") -> 0.7 | P16: =IFERROR(AVERAGE(P8:P14),"") -> 0 | Q16: =IFERROR(AVERAGE(Q8:Q14),"") -> 0.57 | S16: =IFERROR(AVERAGE(S8:S14),"") | U16: SKPIs | W16: 5

Sheet Seguridad OK
A1: KEY | B1: Bloque | C1: N° Preg | D1: Pregunta | E1: Mandatorio | F1: Peso | G1: Guía | H1: Requirimiento | I1: Puntaje | J1: Cómo verificar | K1: Comments | L1: WH - DDC | M1: WH - ABI | N1: ="WH - "&#REF! -> #REF! | O1: DEL - DDC | P1: DEL - ABI | Q1: DEL - 3PL | R1: DDC
B2: Total Pillar Score (Average of Question scores) | L2: =IF(COUNTBLANK(L3:L87)>0,"-", IF(AND(L3="N/A",L69="N/A",L81="N/A"),"N/A", ( N(L5)*$F5+ N(L6)*$F6+ N(L7)*$F7+ N(L8)*$F8+ N(L10)*$F10+ N(L11)*$F11+ N(L12)*$F12+ N(L13)*$F13+ N(L15)*$F15+ N(L16)*$F16+ N(L17)*$F17+ N(L18)*$F18+ N(L19)*$F19+ N(L20)*$F20+ N(L21)*$F21+ N(L23)*$F23+ N(L24)*$F24+ N(L25)*$F25+ N(L27)*$F27+ N(L28)*$F28+ N(L29)*$F29+ N(L30)*$F30+ N(L31)*$F31+ N(L32)*$F32+ N(L34)*$F34+ N(L35)*$F35+ N(L37)*$F37+ N(L38)*$F38+ N(L39)*$F39+ N(L41)*$F41+ N(L42)*$F42+ N(L43)*$F43+ N(L44)*$F44+ N(L45)*$F45+ N(L46)*$F46+ N(L47)*$F47+ N(L48)*$F48+ N(L50)*$F50+ N(L51)*$F51+ N(L51)*$F52+ N(L54)*$F54+ N(L55)*$F55+ N(L56)*$F56+ N(L58)*$F58+ N(L59)*$F59+ N(L61)*$F61+ N(L62)*$F62+ N(L63)*$F63+ N(L64)*$F64+ N(L65)*$F65+ N(L67)*$F67+ N(L68)*$F68+ N(L71)*$F71+ N(L72)*$F72+ N(L73)*$F73+ N(L74)*$F74+ N(L75)*$F75+ N(L77)*$F77+ N(L78)*$F78+ N(L79)*$F79+ N(L80)*$F80+ N(L83)*$F83+ N(L84)*$F84+ N(L85)*$F85+ N(L86)*$F86+ N(L87)*$F87) /( IF(L5="N/A",0,$F5*5)+ IF(L6="N/A",0,$F6*5)+ IF(L7="N/A",0,$F7*5)+ IF(L8="N/A",0,$F8*5)+ IF(L10="N/A",0,$F10*5)+ IF(L11="N/A",0,$F11*5)+ IF(L12="N/A",0,$F12*5)+ IF(L13="N/A",0,$F13*5)+ IF(L15="N/A",0,$F15*5)+ IF(L16="N/A",0,$F16*5)+ IF(L17="N/A",0,$F17*5)+ IF(L18="N/A",0,$F18*5)+ IF(L19="N/A",0,$F19*5)+ IF(L20="N/A",0,$F20*5)+ IF(L21="N/A",0,$F21*5)+ IF(L23="N/A",0,$F23*5)+ IF(L24="N/A",0,$F24*5)+ IF(L25="N/A",0,$F25*5)+ IF(L27="N/A",0,$F27*5)+ IF(L28="N/A",0,$F28*5)+ IF(L29="N/A",0,$F29*5)+ IF(L30="N/A",0,$F30*5)+ IF(L31="N/A",0,$F31*5)+ IF(L32="N/A",0,$F32*5)+ IF(L34="N/A",0,$F34*5)+ IF(L35="N/A",0,$F35*5)+ IF(L37="N/A",0,$F37*5)+ IF(L38="N/A",0,$F38*5)+ IF(L39="N/A",0,$F39*5)+ IF(L41="N/A",0,$F41*5)+ IF(L42="N/A",0,$F42*5)+ IF(L43="N/A",0,$F43*5)+ IF(L44="N/A",0,$F44*5)+ IF(L45="N/A",0,$F45*5)+ IF(L46="N/A",0,$F46*5)+ IF(L47="N/A",0,$F47*5)+ IF(L48="N/A",0,$F48*5)+ IF(L50="N/A",0,$F50*5)+ IF(L51="N/A",0,$F51*5)+ IF(L52="N/A",0,$F52*5)+ IF(L54="N/A",0,$F54*5)+ IF(L55="N/A",0,$F55*5)+ IF(L56="N/A",0,$F56*5)+ IF(L58="N/A",0,$F58*5)+ IF(L59="N/A",0,$F59*5)+ IF(L61="N/A",0,$F61*5)+ IF(L62="N/A",0,$F62*5)+ IF(L63="N/A",0,$F63*5)+ IF(L64="N/A",0,$F64*5)+ IF(L65="N/A",0,$F65*5)+ IF(L67="N/A",0,$F67*5)+ IF(L68="N/A",0,$F68*5)+ IF(L71="N/A",0,$F71*5)+ IF(L72="N/A",0,$F72*5)+ IF(L73="N/A",0,$F73*5)+ IF(L74="N/A",0,$F74*5)+ IF(L75="N/A",0,$F75*5)+ IF(L77="N/A",0,$F77*5)+ IF(L78="N/A",0,$F78*5)+ IF(L79="N/A",0,$F79*5)+ IF(L80="N/A",0,$F80*5)+ IF(L83="N/A",0,$F83*5)+ IF(L84="N/A",0,$F84*5)+ IF(L85="N/A",0,$F85*5)+ IF(L86="N/A",0,$F86*5)+ IF(L87="N/A",0,$F87*5)))) -> 0 | M2: =IF(COUNTBLANK(M3:M87)>0,"-", IF(AND(M3="N/A",M69="N/A",M81="N/A"),"N/A", ( N(M5)*$F5+ N(M6)*$F6+ N(M7)*$F7+ N(M8)*$F8+ N(M10)*$F10+ N(M11)*$F11+ N(M12)*$F12+ N(M13)*$F13+ N(M15)*$F15+ N(M16)*$F16+ N(M17)*$F17+ N(M18)*$F18+ N(M19)*$F19+ N(M20)*$F20+ N(M21)*$F21+ N(M23)*$F23+ N(M24)*$F24+ N(M25)*$F25+ N(M27)*$F27+ N(M28)*$F28+ N(M29)*$F29+ N(M30)*$F30+ N(M31)*$F31+ N(M32)*$F32+ N(M34)*$F34+ N(M35)*$F35+ N(M37)*$F37+ N(M38)*$F38+ N(M39)*$F39+ N(M41)*$F41+ N(M42)*$F42+ N(M43)*$F43+ N(M44)*$F44+ N(M45)*$F45+ N(M46)*$F46+ N(M47)*$F47+ N(M48)*$F48+ N(M50)*$F50+ N(M51)*$F51+ N(M51)*$F52+ N(M54)*$F54+ N(M55)*$F55+ N(M56)*$F56+ N(M58)*$F58+ N(M59)*$F59+ N(M61)*$F61+ N(M62)*$F62+ N(M63)*$F63+ N(M64)*$F64+ N(M65)*$F65+ N(M67)*$F67+ N(M68)*$F68+ N(M71)*$F71+ N(M72)*$F72+ N(M73)*$F73+ N(M74)*$F74+ N(M75)*$F75+ N(M77)*$F77+ N(M78)*$F78+ N(M79)*$F79+ N(M80)*$F80+ N(M83)*$F83+ N(M84)*$F84+ N(M85)*$F85+ N(M86)*$F86+ N(M87)*$F87) /( IF(M5="N/A",0,$F5*5)+ IF(M6="N/A",0,$F6*5)+ IF(M7="N/A",0,$F7*5)+ IF(M8="N/A",0,$F8*5)+ IF(M10="N/A",0,$F10*5)+ IF(M11="N/A",0,$F11*5)+ IF(M12="N/A",0,$F12*5)+ IF(M13="N/A",0,$F13*5)+ IF(M15="N/A",0,$F15*5)+ IF(M16="N/A",0,$F16*5)+ IF(M17="N/A",0,$F17*5)+ IF(M18="N/A",0,$F18*5)+ IF(M19="N/A",0,$F19*5)+ IF(M20="N/A",0,$F20*5)+ IF(M21="N/A",0,$F21*5)+ IF(M23="N/A",0,$F23*5)+ IF(M24="N/A",0,$F24*5)+ IF(M25="N/A",0,$F25*5)+ IF(M27="N/A",0,$F27*5)+ IF(M28="N/A",0,$F28*5)+ IF(M29="N/A",0,$F29*5)+ IF(M30="N/A",0,$F30*5)+ IF(M31="N/A",0,$F31*5)+ IF(M32="N/A",0,$F32*5)+ IF(M34="N/A",0,$F34*5)+ IF(M35="N/A",0,$F35*5)+ IF(M37="N/A",0,$F37*5)+ IF(M38="N/A",0,$F38*5)+ IF(M39="N/A",0,$F39*5)+ IF(M41="N/A",0,$F41*5)+ IF(M42="N/A",0,$F42*5)+ IF(M43="N/A",0,$F43*5)+ IF(M44="N/A",0,$F44*5)+ IF(M45="N/A",0,$F45*5)+ IF(M46="N/A",0,$F46*5)+ IF(M47="N/A",0,$F47*5)+ IF(M48="N/A",0,$F48*5)+ IF(M50="N/A",0,$F50*5)+ IF(M51="N/A",0,$F51*5)+ IF(M52="N/A",0,$F52*5)+ IF(M54="N/A",0,$F54*5)+ IF(M55="N/A",0,$F55*5)+ IF(M56="N/A",0,$F56*5)+ IF(M58="N/A",0,$F58*5)+ IF(M59="N/A",0,$F59*5)+ IF(M61="N/A",0,$F61*5)+ IF(M62="N/A",0,$F62*5)+ IF(M63="N/A",0,$F63*5)+ IF(M64="N/A",0,$F64*5)+ IF(M65="N/A",0,$F65*5)+ IF(M67="N/A",0,$F67*5)+ IF(M68="N/A",0,$F68*5)+ IF(M71="N/A",0,$F71*5)+ IF(M72="N/A",0,$F72*5)+ IF(M73="N/A",0,$F73*5)+ IF(M74="N/A",0,$F74*5)+ IF(M75="N/A",0,$F75*5)+ IF(M77="N/A",0,$F77*5)+ IF(M78="N/A",0,$F78*5)+ IF(M79="N/A",0,$F79*5)+ IF(M80="N/A",0,$F80*5)+ IF(M83="N/A",0,$F83*5)+ IF(M84="N/A",0,$F84*5)+ IF(M85="N/A",0,$F85*5)+ IF(M86="N/A",0,$F86*5)+ IF(M87="N/A",0,$F87*5)))) -> 0 | N2: =IF(COUNTBLANK(N3:N87)>0,"-", IF(AND(N3="N/A",N69="N/A",N81="N/A"),"N/A", ( N(N5)*$F5+ N(N6)*$F6+ N(N7)*$F7+ N(N8)*$F8+ N(N10)*$F10+ N(N11)*$F11+ N(N12)*$F12+ N(N13)*$F13+ N(N15)*$F15+ N(N16)*$F16+ N(N17)*$F17+ N(N18)*$F18+ N(N19)*$F19+ N(N20)*$F20+ N(N21)*$F21+ N(N23)*$F23+ N(N24)*$F24+ N(N25)*$F25+ N(N27)*$F27+ N(N28)*$F28+ N(N29)*$F29+ N(N30)*$F30+ N(N31)*$F31+ N(N32)*$F32+ N(N34)*$F34+ N(N35)*$F35+ N(N37)*$F37+ N(N38)*$F38+ N(N39)*$F39+ N(N41)*$F41+ N(N42)*$F42+ N(N43)*$F43+ N(N44)*$F44+ N(N45)*$F45+ N(N46)*$F46+ N(N47)*$F47+ N(N48)*$F48+ N(N50)*$F50+ N(N51)*$F51+ N(N51)*$F52+ N(N54)*$F54+ N(N55)*$F55+ N(N56)*$F56+ N(N58)*$F58+ N(N59)*$F59+ N(N61)*$F61+ N(N62)*$F62+ N(N63)*$F63+ N(N64)*$F64+ N(N65)*$F65+ N(N67)*$F67+ N(N68)*$F68+ N(N71)*$F71+ N(N72)*$F72+ N(N73)*$F73+ N(N74)*$F74+ N(N75)*$F75+ N(N77)*$F77+ N(N78)*$F78+ N(N79)*$F79+ N(N80)*$F80+ N(N83)*$F83+ N(N84)*$F84+ N(N85)*$F85+ N(N86)*$F86+ N(N87)*$F87) /( IF(N5="N/A",0,$F5*5)+ IF(N6="N/A",0,$F6*5)+ IF(N7="N/A",0,$F7*5)+ IF(N8="N/A",0,$F8*5)+ IF(N10="N/A",0,$F10*5)+ IF(N11="N/A",0,$F11*5)+ IF(N12="N/A",0,$F12*5)+ IF(N13="N/A",0,$F13*5)+ IF(N15="N/A",0,$F15*5)+ IF(N16="N/A",0,$F16*5)+ IF(N17="N/A",0,$F17*5)+ IF(N18="N/A",0,$F18*5)+ IF(N19="N/A",0,$F19*5)+ IF(N20="N/A",0,$F20*5)+ IF(N21="N/A",0,$F21*5)+ IF(N23="N/A",0,$F23*5)+ IF(N24="N/A",0,$F24*5)+ IF(N25="N/A",0,$F25*5)+ IF(N27="N/A",0,$F27*5)+ IF(N28="N/A",0,$F28*5)+ IF(N29="N/A",0,$F29*5)+ IF(N30="N/A",0,$F30*5)+ IF(N31="N/A",0,$F31*5)+ IF(N32="N/A",0,$F32*5)+ IF(N34="N/A",0,$F34*5)+ IF(N35="N/A",0,$F35*5)+ IF(N37="N/A",0,$F37*5)+ IF(N38="N/A",0,$F38*5)+ IF(N39="N/A",0,$F39*5)+ IF(N41="N/A",0,$F41*5)+ IF(N42="N/A",0,$F42*5)+ IF(N43="N/A",0,$F43*5)+ IF(N44="N/A",0,$F44*5)+ IF(N45="N/A",0,$F45*5)+ IF(N46="N/A",0,$F46*5)+ IF(N47="N/A",0,$F47*5)+ IF(N48="N/A",0,$F48*5)+ IF(N50="N/A",0,$F50*5)+ IF(N51="N/A",0,$F51*5)+ IF(N52="N/A",0,$F52*5)+ IF(N54="N/A",0,$F54*5)+ IF(N55="N/A",0,$F55*5)+ IF(N56="N/A",0,$F56*5)+ IF(N58="N/A",0,$F58*5)+ IF(N59="N/A",0,$F59*5)+ IF(N61="N/A",0,$F61*5)+ IF(N62="N/A",0,$F62*5)+ IF(N63="N/A",0,$F63*5)+ IF(N64="N/A",0,$F64*5)+ IF(N65="N/A",0,$F65*5)+ IF(N67="N/A",0,$F67*5)+ IF(N68="N/A",0,$F68*5)+ IF(N71="N/A",0,$F71*5)+ IF(N72="N/A",0,$F72*5)+ IF(N73="N/A",0,$F73*5)+ IF(N74="N/A",0,$F74*5)+ IF(N75="N/A",0,$F75*5)+ IF(N77="N/A",0,$F77*5)+ IF(N78="N/A",0,$F78*5)+ IF(N79="N/A",0,$F79*5)+ IF(N80="N/A",0,$F80*5)+ IF(N83="N/A",0,$F83*5)+ IF(N84="N/A",0,$F84*5)+ IF(N85="N/A",0,$F85*5)+ IF(N86="N/A",0,$F86*5)+ IF(N87="N/A",0,$F87*5)))) -> #DIV/0! | O2: =IF(COUNTBLANK(O3:O87)>0,"-", IF(AND(O3="N/A",O69="N/A",O81="N/A"),"N/A", ( N(O5)*$F5+ N(O6)*$F6+ N(O7)*$F7+ N(O8)*$F8+ N(O10)*$F10+ N(O11)*$F11+ N(O12)*$F12+ N(O13)*$F13+ N(O15)*$F15+ N(O16)*$F16+ N(O17)*$F17+ N(O18)*$F18+ N(O19)*$F19+ N(O20)*$F20+ N(O21)*$F21+ N(O23)*$F23+ N(O24)*$F24+ N(O25)*$F25+ N(O27)*$F27+ N(O28)*$F28+ N(O29)*$F29+ N(O30)*$F30+ N(O31)*$F31+ N(O32)*$F32+ N(O34)*$F34+ N(O35)*$F35+ N(O37)*$F37+ N(O38)*$F38+ N(O39)*$F39+ N(O41)*$F41+ N(O42)*$F42+ N(O43)*$F43+ N(O44)*$F44+ N(O45)*$F45+ N(O46)*$F46+ N(O47)*$F47+ N(O48)*$F48+ N(O50)*$F50+ N(O51)*$F51+ N(O51)*$F52+ N(O54)*$F54+ N(O55)*$F55+ N(O56)*$F56+ N(O58)*$F58+ N(O59)*$F59+ N(O61)*$F61+ N(O62)*$F62+ N(O63)*$F63+ N(O64)*$F64+ N(O65)*$F65+ N(O67)*$F67+ N(O68)*$F68+ N(O71)*$F71+ N(O72)*$F72+ N(O73)*$F73+ N(O74)*$F74+ N(O75)*$F75+ N(O77)*$F77+ N(O78)*$F78+ N(O79)*$F79+ N(O80)*$F80+ N(O83)*$F83+ N(O84)*$F84+ N(O85)*$F85+ N(O86)*$F86+ N(O87)*$F87) /( IF(O5="N/A",0,$F5*5)+ IF(O6="N/A",0,$F6*5)+ IF(O7="N/A",0,$F7*5)+ IF(O8="N/A",0,$F8*5)+ IF(O10="N/A",0,$F10*5)+ IF(O11="N/A",0,$F11*5)+ IF(O12="N/A",0,$F12*5)+ IF(O13="N/A",0,$F13*5)+ IF(O15="N/A",0,$F15*5)+ IF(O16="N/A",0,$F16*5)+ IF(O17="N/A",0,$F17*5)+ IF(O18="N/A",0,$F18*5)+ IF(O19="N/A",0,$F19*5)+ IF(O20="N/A",0,$F20*5)+ IF(O21="N/A",0,$F21*5)+ IF(O23="N/A",0,$F23*5)+ IF(O24="N/A",0,$F24*5)+ IF(O25="N/A",0,$F25*5)+ IF(O27="N/A",0,$F27*5)+ IF(O28="N/A",0,$F28*5)+ IF(O29="N/A",0,$F29*5)+ IF(O30="N/A",0,$F30*5)+ IF(O31="N/A",0,$F31*5)+ IF(O32="N/A",0,$F32*5)+ IF(O34="N/A",0,$F34*5)+ IF(O35="N/A",0,$F35*5)+ IF(O37="N/A",0,$F37*5)+ IF(O38="N/A",0,$F38*5)+ IF(O39="N/A",0,$F39*5)+ IF(O41="N/A",0,$F41*5)+ IF(O42="N/A",0,$F42*5)+ IF(O43="N/A",0,$F43*5)+ IF(O44="N/A",0,$F44*5)+ IF(O45="N/A",0,$F45*5)+ IF(O46="N/A",0,$F46*5)+ IF(O47="N/A",0,$F47*5)+ IF(O48="N/A",0,$F48*5)+ IF(O50="N/A",0,$F50*5)+ IF(O51="N/A",0,$F51*5)+ IF(O52="N/A",0,$F52*5)+ IF(O54="N/A",0,$F54*5)+ IF(O55="N/A",0,$F55*5)+ IF(O56="N/A",0,$F56*5)+ IF(O58="N/A",0,$F58*5)+ IF(O59="N/A",0,$F59*5)+ IF(O61="N/A",0,$F61*5)+ IF(O62="N/A",0,$F62*5)+ IF(O63="N/A",0,$F63*5)+ IF(O64="N/A",0,$F64*5)+ IF(O65="N/A",0,$F65*5)+ IF(O67="N/A",0,$F67*5)+ IF(O68="N/A",0,$F68*5)+ IF(O71="N/A",0,$F71*5)+ IF(O72="N/A",0,$F72*5)+ IF(O73="N/A",0,$F73*5)+ IF(O74="N/A",0,$F74*5)+ IF(O75="N/A",0,$F75*5)+ IF(O77="N/A",0,$F77*5)+ IF(O78="N/A",0,$F78*5)+ IF(O79="N/A",0,$F79*5)+ IF(O80="N/A",0,$F80*5)+ IF(O83="N/A",0,$F83*5)+ IF(O84="N/A",0,$F84*5)+ IF(O85="N/A",0,$F85*5)+ IF(O86="N/A",0,$F86*5)+ IF(O87="N/A",0,$F87*5)))) -> 0 | P2: =IF(COUNTBLANK(P3:P87)>0,"-", IF(AND(P3="N/A",P69="N/A",P81="N/A"),"N/A", ( N(P5)*$F5+ N(P6)*$F6+ N(P7)*$F7+ N(P8)*$F8+ N(P10)*$F10+ N(P11)*$F11+ N(P12)*$F12+ N(P13)*$F13+ N(P15)*$F15+ N(P16)*$F16+ N(P17)*$F17+ N(P18)*$F18+ N(P19)*$F19+ N(P20)*$F20+ N(P21)*$F21+ N(P23)*$F23+ N(P24)*$F24+ N(P25)*$F25+ N(P27)*$F27+ N(P28)*$F28+ N(P29)*$F29+ N(P30)*$F30+ N(P31)*$F31+ N(P32)*$F32+ N(P34)*$F34+ N(P35)*$F35+ N(P37)*$F37+ N(P38)*$F38+ N(P39)*$F39+ N(P41)*$F41+ N(P42)*$F42+ N(P43)*$F43+ N(P44)*$F44+ N(P45)*$F45+ N(P46)*$F46+ N(P47)*$F47+ N(P48)*$F48+ N(P50)*$F50+ N(P51)*$F51+ N(P51)*$F52+ N(P54)*$F54+ N(P55)*$F55+ N(P56)*$F56+ N(P58)*$F58+ N(P59)*$F59+ N(P61)*$F61+ N(P62)*$F62+ N(P63)*$F63+ N(P64)*$F64+ N(P65)*$F65+ N(P67)*$F67+ N(P68)*$F68+ N(P71)*$F71+ N(P72)*$F72+ N(P73)*$F73+ N(P74)*$F74+ N(P75)*$F75+ N(P77)*$F77+ N(P78)*$F78+ N(P79)*$F79+ N(P80)*$F80+ N(P83)*$F83+ N(P84)*$F84+ N(P85)*$F85+ N(P86)*$F86+ N(P87)*$F87) /( IF(P5="N/A",0,$F5*5)+ IF(P6="N/A",0,$F6*5)+ IF(P7="N/A",0,$F7*5)+ IF(P8="N/A",0,$F8*5)+ IF(P10="N/A",0,$F10*5)+ IF(P11="N/A",0,$F11*5)+ IF(P12="N/A",0,$F12*5)+ IF(P13="N/A",0,$F13*5)+ IF(P15="N/A",0,$F15*5)+ IF(P16="N/A",0,$F16*5)+ IF(P17="N/A",0,$F17*5)+ IF(P18="N/A",0,$F18*5)+ IF(P19="N/A",0,$F19*5)+ IF(P20="N/A",0,$F20*5)+ IF(P21="N/A",0,$F21*5)+ IF(P23="N/A",0,$F23*5)+ IF(P24="N/A",0,$F24*5)+ IF(P25="N/A",0,$F25*5)+ IF(P27="N/A",0,$F27*5)+ IF(P28="N/A",0,$F28*5)+ IF(P29="N/A",0,$F29*5)+ IF(P30="N/A",0,$F30*5)+ IF(P31="N/A",0,$F31*5)+ IF(P32="N/A",0,$F32*5)+ IF(P34="N/A",0,$F34*5)+ IF(P35="N/A",0,$F35*5)+ IF(P37="N/A",0,$F37*5)+ IF(P38="N/A",0,$F38*5)+ IF(P39="N/A",0,$F39*5)+ IF(P41="N/A",0,$F41*5)+ IF(P42="N/A",0,$F42*5)+ IF(P43="N/A",0,$F43*5)+ IF(P44="N/A",0,$F44*5)+ IF(P45="N/A",0,$F45*5)+ IF(P46="N/A",0,$F46*5)+ IF(P47="N/A",0,$F47*5)+ IF(P48="N/A",0,$F48*5)+ IF(P50="N/A",0,$F50*5)+ IF(P51="N/A",0,$F51*5)+ IF(P52="N/A",0,$F52*5)+ IF(P54="N/A",0,$F54*5)+ IF(P55="N/A",0,$F55*5)+ IF(P56="N/A",0,$F56*5)+ IF(P58="N/A",0,$F58*5)+ IF(P59="N/A",0,$F59*5)+ IF(P61="N/A",0,$F61*5)+ IF(P62="N/A",0,$F62*5)+ IF(P63="N/A",0,$F63*5)+ IF(P64="N/A",0,$F64*5)+ IF(P65="N/A",0,$F65*5)+ IF(P67="N/A",0,$F67*5)+ IF(P68="N/A",0,$F68*5)+ IF(P71="N/A",0,$F71*5)+ IF(P72="N/A",0,$F72*5)+ IF(P73="N/A",0,$F73*5)+ IF(P74="N/A",0,$F74*5)+ IF(P75="N/A",0,$F75*5)+ IF(P77="N/A",0,$F77*5)+ IF(P78="N/A",0,$F78*5)+ IF(P79="N/A",0,$F79*5)+ IF(P80="N/A",0,$F80*5)+ IF(P83="N/A",0,$F83*5)+ IF(P84="N/A",0,$F84*5)+ IF(P85="N/A",0,$F85*5)+ IF(P86="N/A",0,$F86*5)+ IF(P87="N/A",0,$F87*5)))) -> 0 | Q2: =IF(COUNTBLANK(Q3:Q87)>0,"-", IF(AND(Q3="N/A",Q69="N/A",Q81="N/A"),"N/A", ( N(Q5)*$F5+ N(Q6)*$F6+ N(Q7)*$F7+ N(Q8)*$F8+ N(Q10)*$F10+ N(Q11)*$F11+ N(Q12)*$F12+ N(Q13)*$F13+ N(Q15)*$F15+ N(Q16)*$F16+ N(Q17)*$F17+ N(Q18)*$F18+ N(Q19)*$F19+ N(Q20)*$F20+ N(Q21)*$F21+ N(Q23)*$F23+ N(Q24)*$F24+ N(Q25)*$F25+ N(Q27)*$F27+ N(Q28)*$F28+ N(Q29)*$F29+ N(Q30)*$F30+ N(Q31)*$F31+ N(Q32)*$F32+ N(Q34)*$F34+ N(Q35)*$F35+ N(Q37)*$F37+ N(Q38)*$F38+ N(Q39)*$F39+ N(Q41)*$F41+ N(Q42)*$F42+ N(Q43)*$F43+ N(Q44)*$F44+ N(Q45)*$F45+ N(Q46)*$F46+ N(Q47)*$F47+ N(Q48)*$F48+ N(Q50)*$F50+ N(Q51)*$F51+ N(Q51)*$F52+ N(Q54)*$F54+ N(Q55)*$F55+ N(Q56)*$F56+ N(Q58)*$F58+ N(Q59)*$F59+ N(Q61)*$F61+ N(Q62)*$F62+ N(Q63)*$F63+ N(Q64)*$F64+ N(Q65)*$F65+ N(Q67)*$F67+ N(Q68)*$F68+ N(Q71)*$F71+ N(Q72)*$F72+ N(Q73)*$F73+ N(Q74)*$F74+ N(Q75)*$F75+ N(Q77)*$F77+ N(Q78)*$F78+ N(Q79)*$F79+ N(Q80)*$F80+ N(Q83)*$F83+ N(Q84)*$F84+ N(Q85)*$F85+ N(Q86)*$F86+ N(Q87)*$F87) /( IF(Q5="N/A",0,$F5*5)+ IF(Q6="N/A",0,$F6*5)+ IF(Q7="N/A",0,$F7*5)+ IF(Q8="N/A",0,$F8*5)+ IF(Q10="N/A",0,$F10*5)+ IF(Q11="N/A",0,$F11*5)+ IF(Q12="N/A",0,$F12*5)+ IF(Q13="N/A",0,$F13*5)+ IF(Q15="N/A",0,$F15*5)+ IF(Q16="N/A",0,$F16*5)+ IF(Q17="N/A",0,$F17*5)+ IF(Q18="N/A",0,$F18*5)+ IF(Q19="N/A",0,$F19*5)+ IF(Q20="N/A",0,$F20*5)+ IF(Q21="N/A",0,$F21*5)+ IF(Q23="N/A",0,$F23*5)+ IF(Q24="N/A",0,$F24*5)+ IF(Q25="N/A",0,$F25*5)+ IF(Q27="N/A",0,$F27*5)+ IF(Q28="N/A",0,$F28*5)+ IF(Q29="N/A",0,$F29*5)+ IF(Q30="N/A",0,$F30*5)+ IF(Q31="N/A",0,$F31*5)+ IF(Q32="N/A",0,$F32*5)+ IF(Q34="N/A",0,$F34*5)+ IF(Q35="N/A",0,$F35*5)+ IF(Q37="N/A",0,$F37*5)+ IF(Q38="N/A",0,$F38*5)+ IF(Q39="N/A",0,$F39*5)+ IF(Q41="N/A",0,$F41*5)+ IF(Q42="N/A",0,$F42*5)+ IF(Q43="N/A",0,$F43*5)+ IF(Q44="N/A",0,$F44*5)+ IF(Q45="N/A",0,$F45*5)+ IF(Q46="N/A",0,$F46*5)+ IF(Q47="N/A",0,$F47*5)+ IF(Q48="N/A",0,$F48*5)+ IF(Q50="N/A",0,$F50*5)+ IF(Q51="N/A",0,$F51*5)+ IF(Q52="N/A",0,$F52*5)+ IF(Q54="N/A",0,$F54*5)+ IF(Q55="N/A",0,$F55*5)+ IF(Q56="N/A",0,$F56*5)+ IF(Q58="N/A",0,$F58*5)+ IF(Q59="N/A",0,$F59*5)+ IF(Q61="N/A",0,$F61*5)+ IF(Q62="N/A",0,$F62*5)+ IF(Q63="N/A",0,$F63*5)+ IF(Q64="N/A",0,$F64*5)+ IF(Q65="N/A",0,$F65*5)+ IF(Q67="N/A",0,$F67*5)+ IF(Q68="N/A",0,$F68*5)+ IF(Q71="N/A",0,$F71*5)+ IF(Q72="N/A",0,$F72*5)+ IF(Q73="N/A",0,$F73*5)+ IF(Q74="N/A",0,$F74*5)+ IF(Q75="N/A",0,$F75*5)+ IF(Q77="N/A",0,$F77*5)+ IF(Q78="N/A",0,$F78*5)+ IF(Q79="N/A",0,$F79*5)+ IF(Q80="N/A",0,$F80*5)+ IF(Q83="N/A",0,$F83*5)+ IF(Q84="N/A",0,$F84*5)+ IF(Q85="N/A",0,$F85*5)+ IF(Q86="N/A",0,$F86*5)+ IF(Q87="N/A",0,$F87*5)))) -> #DIV/0! | R2: =IF(COUNTBLANK(R3:R87)>0,"-", IF(AND(R3="N/A",R69="N/A",R81="N/A"),"N/A", ( N(R5)*$F5+ N(R6)*$F6+ N(R7)*$F7+ N(R8)*$F8+ N(R10)*$F10+ N(R11)*$F11+ N(R12)*$F12+ N(R13)*$F13+ N(R15)*$F15+ N(R16)*$F16+ N(R17)*$F17+ N(R18)*$F18+ N(R19)*$F19+ N(R20)*$F20+ N(R21)*$F21+ N(R23)*$F23+ N(R24)*$F24+ N(R25)*$F25+ N(R27)*$F27+ N(R28)*$F28+ N(R29)*$F29+ N(R30)*$F30+ N(R31)*$F31+ N(R32)*$F32+ N(R34)*$F34+ N(R35)*$F35+ N(R37)*$F37+ N(R38)*$F38+ N(R39)*$F39+ N(R41)*$F41+ N(R42)*$F42+ N(R43)*$F43+ N(R44)*$F44+ N(R45)*$F45+ N(R46)*$F46+ N(R47)*$F47+ N(R48)*$F48+ N(R50)*$F50+ N(R51)*$F51+ N(R51)*$F52+ N(R54)*$F54+ N(R55)*$F55+ N(R56)*$F56+ N(R58)*$F58+ N(R59)*$F59+ N(R61)*$F61+ N(R62)*$F62+ N(R63)*$F63+ N(R64)*$F64+ N(R65)*$F65+ N(R67)*$F67+ N(R68)*$F68+ N(R71)*$F71+ N(R72)*$F72+ N(R73)*$F73+ N(R74)*$F74+ N(R75)*$F75+ N(R77)*$F77+ N(R78)*$F78+ N(R79)*$F79+ N(R80)*$F80+ N(R83)*$F83+ N(R84)*$F84+ N(R85)*$F85+ N(R86)*$F86+ N(R87)*$F87) /( IF(R5="N/A",0,$F5*5)+ IF(R6="N/A",0,$F6*5)+ IF(R7="N/A",0,$F7*5)+ IF(R8="N/A",0,$F8*5)+ IF(R10="N/A",0,$F10*5)+ IF(R11="N/A",0,$F11*5)+ IF(R12="N/A",0,$F12*5)+ IF(R13="N/A",0,$F13*5)+ IF(R15="N/A",0,$F15*5)+ IF(R16="N/A",0,$F16*5)+ IF(R17="N/A",0,$F17*5)+ IF(R18="N/A",0,$F18*5)+ IF(R19="N/A",0,$F19*5)+ IF(R20="N/A",0,$F20*5)+ IF(R21="N/A",0,$F21*5)+ IF(R23="N/A",0,$F23*5)+ IF(R24="N/A",0,$F24*5)+ IF(R25="N/A",0,$F25*5)+ IF(R27="N/A",0,$F27*5)+ IF(R28="N/A",0,$F28*5)+ IF(R29="N/A",0,$F29*5)+ IF(R30="N/A",0,$F30*5)+ IF(R31="N/A",0,$F31*5)+ IF(R32="N/A",0,$F32*5)+ IF(R34="N/A",0,$F34*5)+ IF(R35="N/A",0,$F35*5)+ IF(R37="N/A",0,$F37*5)+ IF(R38="N/A",0,$F38*5)+ IF(R39="N/A",0,$F39*5)+ IF(R41="N/A",0,$F41*5)+ IF(R42="N/A",0,$F42*5)+ IF(R43="N/A",0,$F43*5)+ IF(R44="N/A",0,$F44*5)+ IF(R45="N/A",0,$F45*5)+ IF(R46="N/A",0,$F46*5)+ IF(R47="N/A",0,$F47*5)+ IF(R48="N/A",0,$F48*5)+ IF(R50="N/A",0,$F50*5)+ IF(R51="N/A",0,$F51*5)+ IF(R52="N/A",0,$F52*5)+ IF(R54="N/A",0,$F54*5)+ IF(R55="N/A",0,$F55*5)+ IF(R56="N/A",0,$F56*5)+ IF(R58="N/A",0,$F58*5)+ IF(R59="N/A",0,$F59*5)+ IF(R61="N/A",0,$F61*5)+ IF(R62="N/A",0,$F62*5)+ IF(R63="N/A",0,$F63*5)+ IF(R64="N/A",0,$F64*5)+ IF(R65="N/A",0,$F65*5)+ IF(R67="N/A",0,$F67*5)+ IF(R68="N/A",0,$F68*5)+ IF(R71="N/A",0,$F71*5)+ IF(R72="N/A",0,$F72*5)+ IF(R73="N/A",0,$F73*5)+ IF(R74="N/A",0,$F74*5)+ IF(R75="N/A",0,$F75*5)+ IF(R77="N/A",0,$F77*5)+ IF(R78="N/A",0,$F78*5)+ IF(R79="N/A",0,$F79*5)+ IF(R80="N/A",0,$F80*5)+ IF(R83="N/A",0,$F83*5)+ IF(R84="N/A",0,$F84*5)+ IF(R85="N/A",0,$F85*5)+ IF(R86="N/A",0,$F86*5)+ IF(R87="N/A",0,$F87*5)))) -> 0
B3: FUNDAMENTALES | L3: =IF(COUNTBLANK(L4:L68)>0,"-", IF(AND(L4="N/A",L9="N/A",L14="N/A",L22="N/A",L26="N/A",L33="N/A",L36="N/A",L40="N/A",L49="N/A",L53="N/A",L57="N/A",L60="N/A",L66="N/A"),"N/A", (N(L5)*$F5+ N(L6)*$F6+ N(L7)*$F7+ N(L8)*$F8+ N(L10)*$F10+ N(L11)*$F11+ N(L12)*$F12+ N(L13)*$F13+ N(L15)*$F15+ N(L16)*$F16+ N(L17)*$F17+ N(L18)*$F18+ N(L19)*$F19+ N(L20)*$F20+ N(L21)*$F21+ N(L23)*$F23+ N(L24)*$F24+ N(L25)*$F25+ N(L27)*$F27+ N(L28)*$F28+ N(L29)*$F29+ N(L30)*$F30+ N(L31)*$F31+ N(L32)*$F32+ N(L34)*$F34+ N(L35)*$F35+ N(L37)*$F37+ N(L38)*$F38+ N(L39)*$F39+ N(L41)*$F41+ N(L42)*$F42+ N(L43)*$F43+ N(L44)*$F44+ N(L45)*$F45+ N(L46)*$F46+ N(L47)*$F47+ N(L48)*$F48+ N(L50)*$F50+ N(L51)*$F51+ N(L51)*$F52+ N(L54)*$F54+ N(L55)*$F55+ N(L56)*$F56+ N(L58)*$F58+ N(L59)*$F59+ N(L61)*$F61+ N(L62)*$F62+ N(L63)*$F63+ N(L64)*$F64+ N(L65)*$F65+ N(L67)*$F67+ N(L68)*$F68)/ (IF(L5="N/A",0,$F5*5)+ IF(L6="N/A",0,$F6*5)+ IF(L7="N/A",0,$F7*5)+ IF(L8="N/A",0,$F8*5)+ IF(L10="N/A",0,$F10*5)+ IF(L11="N/A",0,$F11*5)+ IF(L12="N/A",0,$F12*5)+ IF(L13="N/A",0,$F13*5)+ IF(L15="N/A",0,$F15*5)+ IF(L16="N/A",0,$F16*5)+ IF(L17="N/A",0,$F17*5)+ IF(L18="N/A",0,$F18*5)+ IF(L19="N/A",0,$F19*5)+ IF(L20="N/A",0,$F20*5)+ IF(L21="N/A",0,$F21*5)+ IF(L23="N/A",0,$F23*5)+ IF(L24="N/A",0,$F24*5)+ IF(L25="N/A",0,$F25*5)+ IF(L27="N/A",0,$F27*5)+ IF(L28="N/A",0,$F28*5)+ IF(L29="N/A",0,$F29*5)+ IF(L30="N/A",0,$F30*5)+ IF(L31="N/A",0,$F31*5)+ IF(L32="N/A",0,$F32*5)+ IF(L34="N/A",0,$F34*5)+ IF(L35="N/A",0,$F35*5)+ IF(L37="N/A",0,$F37*5)+ IF(L38="N/A",0,$F38*5)+ IF(L39="N/A",0,$F39*5)+ IF(L41="N/A",0,$F41*5)+ IF(L42="N/A",0,$F42*5)+ IF(L43="N/A",0,$F43*5)+ IF(L44="N/A",0,$F44*5)+ IF(L45="N/A",0,$F45*5)+ IF(L46="N/A",0,$F46*5)+ IF(L47="N/A",0,$F47*5)+ IF(L48="N/A",0,$F48*5)+ IF(L50="N/A",0,$F50*5)+ IF(L51="N/A",0,$F51*5)+ IF(L52="N/A",0,$F52*5)++ IF(L54="N/A",0,$F54*5)+ IF(L55="N/A",0,$F55*5)+ IF(L56="N/A",0,$F56*5)+ IF(L58="N/A",0,$F58*5)+ IF(L59="N/A",0,$F59*5)+ IF(L61="N/A",0,$F61*5)+ IF(L62="N/A",0,$F62*5)+ IF(L63="N/A",0,$F63*5)+ IF(L64="N/A",0,$F64*5)+ IF(L65="N/A",0,$F65*5)+ IF(L67="N/A",0,$F67*5)+ IF(L68="N/A",0,$F68*5)))) -> 0 | M3: =IF(COUNTBLANK(M4:M68)>0,"-", IF(AND(M4="N/A",M9="N/A",M14="N/A",M22="N/A",M26="N/A",M33="N/A",M36="N/A",M40="N/A",M49="N/A",M53="N/A",M57="N/A",M60="N/A",M66="N/A"),"N/A", (N(M5)*$F5+ N(M6)*$F6+ N(M7)*$F7+ N(M8)*$F8+ N(M10)*$F10+ N(M11)*$F11+ N(M12)*$F12+ N(M13)*$F13+ N(M15)*$F15+ N(M16)*$F16+ N(M17)*$F17+ N(M18)*$F18+ N(M19)*$F19+ N(M20)*$F20+ N(M21)*$F21+ N(M23)*$F23+ N(M24)*$F24+ N(M25)*$F25+ N(M27)*$F27+ N(M28)*$F28+ N(M29)*$F29+ N(M30)*$F30+ N(M31)*$F31+ N(M32)*$F32+ N(M34)*$F34+ N(M35)*$F35+ N(M37)*$F37+ N(M38)*$F38+ N(M39)*$F39+ N(M41)*$F41+ N(M42)*$F42+ N(M43)*$F43+ N(M44)*$F44+ N(M45)*$F45+ N(M46)*$F46+ N(M47)*$F47+ N(M48)*$F48+ N(M50)*$F50+ N(M51)*$F51+ N(M51)*$F52+ N(M54)*$F54+ N(M55)*$F55+ N(M56)*$F56+ N(M58)*$F58+ N(M59)*$F59+ N(M61)*$F61+ N(M62)*$F62+ N(M63)*$F63+ N(M64)*$F64+ N(M65)*$F65+ N(M67)*$F67+ N(M68)*$F68)/ (IF(M5="N/A",0,$F5*5)+ IF(M6="N/A",0,$F6*5)+ IF(M7="N/A",0,$F7*5)+ IF(M8="N/A",0,$F8*5)+ IF(M10="N/A",0,$F10*5)+ IF(M11="N/A",0,$F11*5)+ IF(M12="N/A",0,$F12*5)+ IF(M13="N/A",0,$F13*5)+ IF(M15="N/A",0,$F15*5)+ IF(M16="N/A",0,$F16*5)+ IF(M17="N/A",0,$F17*5)+ IF(M18="N/A",0,$F18*5)+ IF(M19="N/A",0,$F19*5)+ IF(M20="N/A",0,$F20*5)+ IF(M21="N/A",0,$F21*5)+ IF(M23="N/A",0,$F23*5)+ IF(M24="N/A",0,$F24*5)+ IF(M25="N/A",0,$F25*5)+ IF(M27="N/A",0,$F27*5)+ IF(M28="N/A",0,$F28*5)+ IF(M29="N/A",0,$F29*5)+ IF(M30="N/A",0,$F30*5)+ IF(M31="N/A",0,$F31*5)+ IF(M32="N/A",0,$F32*5)+ IF(M34="N/A",0,$F34*5)+ IF(M35="N/A",0,$F35*5)+ IF(M37="N/A",0,$F37*5)+ IF(M38="N/A",0,$F38*5)+ IF(M39="N/A",0,$F39*5)+ IF(M41="N/A",0,$F41*5)+ IF(M42="N/A",0,$F42*5)+ IF(M43="N/A",0,$F43*5)+ IF(M44="N/A",0,$F44*5)+ IF(M45="N/A",0,$F45*5)+ IF(M46="N/A",0,$F46*5)+ IF(M47="N/A",0,$F47*5)+ IF(M48="N/A",0,$F48*5)+ IF(M50="N/A",0,$F50*5)+ IF(M51="N/A",0,$F51*5)+ IF(M52="N/A",0,$F52*5)++ IF(M54="N/A",0,$F54*5)+ IF(M55="N/A",0,$F55*5)+ IF(M56="N/A",0,$F56*5)+ IF(M58="N/A",0,$F58*5)+ IF(M59="N/A",0,$F59*5)+ IF(M61="N/A",0,$F61*5)+ IF(M62="N/A",0,$F62*5)+ IF(M63="N/A",0,$F63*5)+ IF(M64="N/A",0,$F64*5)+ IF(M65="N/A",0,$F65*5)+ IF(M67="N/A",0,$F67*5)+ IF(M68="N/A",0,$F68*5)))) -> 0 | N3: =IF(COUNTBLANK(N4:N68)>0,"-", IF(AND(N4="N/A",N9="N/A",N14="N/A",N22="N/A",N26="N/A",N33="N/A",N36="N/A",N40="N/A",N49="N/A",N53="N/A",N57="N/A",N60="N/A",N66="N/A"),"N/A", (N(N5)*$F5+ N(N6)*$F6+ N(N7)*$F7+ N(N8)*$F8+ N(N10)*$F10+ N(N11)*$F11+ N(N12)*$F12+ N(N13)*$F13+ N(N15)*$F15+ N(N16)*$F16+ N(N17)*$F17+ N(N18)*$F18+ N(N19)*$F19+ N(N20)*$F20+ N(N21)*$F21+ N(N23)*$F23+ N(N24)*$F24+ N(N25)*$F25+ N(N27)*$F27+ N(N28)*$F28+ N(N29)*$F29+ N(N30)*$F30+ N(N31)*$F31+ N(N32)*$F32+ N(N34)*$F34+ N(N35)*$F35+ N(N37)*$F37+ N(N38)*$F38+ N(N39)*$F39+ N(N41)*$F41+ N(N42)*$F42+ N(N43)*$F43+ N(N44)*$F44+ N(N45)*$F45+ N(N46)*$F46+ N(N47)*$F47+ N(N48)*$F48+ N(N50)*$F50+ N(N51)*$F51+ N(N51)*$F52+ N(N54)*$F54+ N(N55)*$F55+ N(N56)*$F56+ N(N58)*$F58+ N(N59)*$F59+ N(N61)*$F61+ N(N62)*$F62+ N(N63)*$F63+ N(N64)*$F64+ N(N65)*$F65+ N(N67)*$F67+ N(N68)*$F68)/ (IF(N5="N/A",0,$F5*5)+ IF(N6="N/A",0,$F6*5)+ IF(N7="N/A",0,$F7*5)+ IF(N8="N/A",0,$F8*5)+ IF(N10="N/A",0,$F10*5)+ IF(N11="N/A",0,$F11*5)+ IF(N12="N/A",0,$F12*5)+ IF(N13="N/A",0,$F13*5)+ IF(N15="N/A",0,$F15*5)+ IF(N16="N/A",0,$F16*5)+ IF(N17="N/A",0,$F17*5)+ IF(N18="N/A",0,$F18*5)+ IF(N19="N/A",0,$F19*5)+ IF(N20="N/A",0,$F20*5)+ IF(N21="N/A",0,$F21*5)+ IF(N23="N/A",0,$F23*5)+ IF(N24="N/A",0,$F24*5)+ IF(N25="N/A",0,$F25*5)+ IF(N27="N/A",0,$F27*5)+ IF(N28="N/A",0,$F28*5)+ IF(N29="N/A",0,$F29*5)+ IF(N30="N/A",0,$F30*5)+ IF(N31="N/A",0,$F31*5)+ IF(N32="N/A",0,$F32*5)+ IF(N34="N/A",0,$F34*5)+ IF(N35="N/A",0,$F35*5)+ IF(N37="N/A",0,$F37*5)+ IF(N38="N/A",0,$F38*5)+ IF(N39="N/A",0,$F39*5)+ IF(N41="N/A",0,$F41*5)+ IF(N42="N/A",0,$F42*5)+ IF(N43="N/A",0,$F43*5)+ IF(N44="N/A",0,$F44*5)+ IF(N45="N/A",0,$F45*5)+ IF(N46="N/A",0,$F46*5)+ IF(N47="N/A",0,$F47*5)+ IF(N48="N/A",0,$F48*5)+ IF(N50="N/A",0,$F50*5)+ IF(N51="N/A",0,$F51*5)+ IF(N52="N/A",0,$F52*5)++ IF(N54="N/A",0,$F54*5)+ IF(N55="N/A",0,$F55*5)+ IF(N56="N/A",0,$F56*5)+ IF(N58="N/A",0,$F58*5)+ IF(N59="N/A",0,$F59*5)+ IF(N61="N/A",0,$F61*5)+ IF(N62="N/A",0,$F62*5)+ IF(N63="N/A",0,$F63*5)+ IF(N64="N/A",0,$F64*5)+ IF(N65="N/A",0,$F65*5)+ IF(N67="N/A",0,$F67*5)+ IF(N68="N/A",0,$F68*5)))) -> #DIV/0! | O3: =IF(COUNTBLANK(O4:O68)>0,"-", IF(AND(O4="N/A",O9="N/A",O14="N/A",O22="N/A",O26="N/A",O33="N/A",O36="N/A",O40="N/A",O49="N/A",O53="N/A",O57="N/A",O60="N/A",O66="N/A"),"N/A", (N(O5)*$F5+ N(O6)*$F6+ N(O7)*$F7+ N(O8)*$F8+ N(O10)*$F10+ N(O11)*$F11+ N(O12)*$F12+ N(O13)*$F13+ N(O15)*$F15+ N(O16)*$F16+ N(O17)*$F17+ N(O18)*$F18+ N(O19)*$F19+ N(O20)*$F20+ N(O21)*$F21+ N(O23)*$F23+ N(O24)*$F24+ N(O25)*$F25+ N(O27)*$F27+ N(O28)*$F28+ N(O29)*$F29+ N(O30)*$F30+ N(O31)*$F31+ N(O32)*$F32+ N(O34)*$F34+ N(O35)*$F35+ N(O37)*$F37+ N(O38)*$F38+ N(O39)*$F39+ N(O41)*$F41+ N(O42)*$F42+ N(O43)*$F43+ N(O44)*$F44+ N(O45)*$F45+ N(O46)*$F46+ N(O47)*$F47+ N(O48)*$F48+ N(O50)*$F50+ N(O51)*$F51+ N(O51)*$F52+ N(O54)*$F54+ N(O55)*$F55+ N(O56)*$F56+ N(O58)*$F58+ N(O59)*$F59+ N(O61)*$F61+ N(O62)*$F62+ N(O63)*$F63+ N(O64)*$F64+ N(O65)*$F65+ N(O67)*$F67+ N(O68)*$F68)/ (IF(O5="N/A",0,$F5*5)+ IF(O6="N/A",0,$F6*5)+ IF(O7="N/A",0,$F7*5)+ IF(O8="N/A",0,$F8*5)+ IF(O10="N/A",0,$F10*5)+ IF(O11="N/A",0,$F11*5)+ IF(O12="N/A",0,$F12*5)+ IF(O13="N/A",0,$F13*5)+ IF(O15="N/A",0,$F15*5)+ IF(O16="N/A",0,$F16*5)+ IF(O17="N/A",0,$F17*5)+ IF(O18="N/A",0,$F18*5)+ IF(O19="N/A",0,$F19*5)+ IF(O20="N/A",0,$F20*5)+ IF(O21="N/A",0,$F21*5)+ IF(O23="N/A",0,$F23*5)+ IF(O24="N/A",0,$F24*5)+ IF(O25="N/A",0,$F25*5)+ IF(O27="N/A",0,$F27*5)+ IF(O28="N/A",0,$F28*5)+ IF(O29="N/A",0,$F29*5)+ IF(O30="N/A",0,$F30*5)+ IF(O31="N/A",0,$F31*5)+ IF(O32="N/A",0,$F32*5)+ IF(O34="N/A",0,$F34*5)+ IF(O35="N/A",0,$F35*5)+ IF(O37="N/A",0,$F37*5)+ IF(O38="N/A",0,$F38*5)+ IF(O39="N/A",0,$F39*5)+ IF(O41="N/A",0,$F41*5)+ IF(O42="N/A",0,$F42*5)+ IF(O43="N/A",0,$F43*5)+ IF(O44="N/A",0,$F44*5)+ IF(O45="N/A",0,$F45*5)+ IF(O46="N/A",0,$F46*5)+ IF(O47="N/A",0,$F47*5)+ IF(O48="N/A",0,$F48*5)+ IF(O50="N/A",0,$F50*5)+ IF(O51="N/A",0,$F51*5)+ IF(O52="N/A",0,$F52*5)++ IF(O54="N/A",0,$F54*5)+ IF(O55="N/A",0,$F55*5)+ IF(O56="N/A",0,$F56*5)+ IF(O58="N/A",0,$F58*5)+ IF(O59="N/A",0,$F59*5)+ IF(O61="N/A",0,$F61*5)+ IF(O62="N/A",0,$F62*5)+ IF(O63="N/A",0,$F63*5)+ IF(O64="N/A",0,$F64*5)+ IF(O65="N/A",0,$F65*5)+ IF(O67="N/A",0,$F67*5)+ IF(O68="N/A",0,$F68*5)))) -> 0 | P3: =IF(COUNTBLANK(P4:P68)>0,"-", IF(AND(P4="N/A",P9="N/A",P14="N/A",P22="N/A",P26="N/A",P33="N/A",P36="N/A",P40="N/A",P49="N/A",P53="N/A",P57="N/A",P60="N/A",P66="N/A"),"N/A", (N(P5)*$F5+ N(P6)*$F6+ N(P7)*$F7+ N(P8)*$F8+ N(P10)*$F10+ N(P11)*$F11+ N(P12)*$F12+ N(P13)*$F13+ N(P15)*$F15+ N(P16)*$F16+ N(P17)*$F17+ N(P18)*$F18+ N(P19)*$F19+ N(P20)*$F20+ N(P21)*$F21+ N(P23)*$F23+ N(P24)*$F24+ N(P25)*$F25+ N(P27)*$F27+ N(P28)*$F28+ N(P29)*$F29+ N(P30)*$F30+ N(P31)*$F31+ N(P32)*$F32+ N(P34)*$F34+ N(P35)*$F35+ N(P37)*$F37+ N(P38)*$F38+ N(P39)*$F39+ N(P41)*$F41+ N(P42)*$F42+ N(P43)*$F43+ N(P44)*$F44+ N(P45)*$F45+ N(P46)*$F46+ N(P47)*$F47+ N(P48)*$F48+ N(P50)*$F50+ N(P51)*$F51+ N(P51)*$F52+ N(P54)*$F54+ N(P55)*$F55+ N(P56)*$F56+ N(P58)*$F58+ N(P59)*$F59+ N(P61)*$F61+ N(P62)*$F62+ N(P63)*$F63+ N(P64)*$F64+ N(P65)*$F65+ N(P67)*$F67+ N(P68)*$F68)/ (IF(P5="N/A",0,$F5*5)+ IF(P6="N/A",0,$F6*5)+ IF(P7="N/A",0,$F7*5)+ IF(P8="N/A",0,$F8*5)+ IF(P10="N/A",0,$F10*5)+ IF(P11="N/A",0,$F11*5)+ IF(P12="N/A",0,$F12*5)+ IF(P13="N/A",0,$F13*5)+ IF(P15="N/A",0,$F15*5)+ IF(P16="N/A",0,$F16*5)+ IF(P17="N/A",0,$F17*5)+ IF(P18="N/A",0,$F18*5)+ IF(P19="N/A",0,$F19*5)+ IF(P20="N/A",0,$F20*5)+ IF(P21="N/A",0,$F21*5)+ IF(P23="N/A",0,$F23*5)+ IF(P24="N/A",0,$F24*5)+ IF(P25="N/A",0,$F25*5)+ IF(P27="N/A",0,$F27*5)+ IF(P28="N/A",0,$F28*5)+ IF(P29="N/A",0,$F29*5)+ IF(P30="N/A",0,$F30*5)+ IF(P31="N/A",0,$F31*5)+ IF(P32="N/A",0,$F32*5)+ IF(P34="N/A",0,$F34*5)+ IF(P35="N/A",0,$F35*5)+ IF(P37="N/A",0,$F37*5)+ IF(P38="N/A",0,$F38*5)+ IF(P39="N/A",0,$F39*5)+ IF(P41="N/A",0,$F41*5)+ IF(P42="N/A",0,$F42*5)+ IF(P43="N/A",0,$F43*5)+ IF(P44="N/A",0,$F44*5)+ IF(P45="N/A",0,$F45*5)+ IF(P46="N/A",0,$F46*5)+ IF(P47="N/A",0,$F47*5)+ IF(P48="N/A",0,$F48*5)+ IF(P50="N/A",0,$F50*5)+ IF(P51="N/A",0,$F51*5)+ IF(P52="N/A",0,$F52*5)++ IF(P54="N/A",0,$F54*5)+ IF(P55="N/A",0,$F55*5)+ IF(P56="N/A",0,$F56*5)+ IF(P58="N/A",0,$F58*5)+ IF(P59="N/A",0,$F59*5)+ IF(P61="N/A",0,$F61*5)+ IF(P62="N/A",0,$F62*5)+ IF(P63="N/A",0,$F63*5)+ IF(P64="N/A",0,$F64*5)+ IF(P65="N/A",0,$F65*5)+ IF(P67="N/A",0,$F67*5)+ IF(P68="N/A",0,$F68*5)))) -> 0 | Q3: =IF(COUNTBLANK(Q4:Q68)>0,"-", IF(AND(Q4="N/A",Q9="N/A",Q14="N/A",Q22="N/A",Q26="N/A",Q33="N/A",Q36="N/A",Q40="N/A",Q49="N/A",Q53="N/A",Q57="N/A",Q60="N/A",Q66="N/A"),"N/A", (N(Q5)*$F5+ N(Q6)*$F6+ N(Q7)*$F7+ N(Q8)*$F8+ N(Q10)*$F10+ N(Q11)*$F11+ N(Q12)*$F12+ N(Q13)*$F13+ N(Q15)*$F15+ N(Q16)*$F16+ N(Q17)*$F17+ N(Q18)*$F18+ N(Q19)*$F19+ N(Q20)*$F20+ N(Q21)*$F21+ N(Q23)*$F23+ N(Q24)*$F24+ N(Q25)*$F25+ N(Q27)*$F27+ N(Q28)*$F28+ N(Q29)*$F29+ N(Q30)*$F30+ N(Q31)*$F31+ N(Q32)*$F32+ N(Q34)*$F34+ N(Q35)*$F35+ N(Q37)*$F37+ N(Q38)*$F38+ N(Q39)*$F39+ N(Q41)*$F41+ N(Q42)*$F42+ N(Q43)*$F43+ N(Q44)*$F44+ N(Q45)*$F45+ N(Q46)*$F46+ N(Q47)*$F47+ N(Q48)*$F48+ N(Q50)*$F50+ N(Q51)*$F51+ N(Q51)*$F52+ N(Q54)*$F54+ N(Q55)*$F55+ N(Q56)*$F56+ N(Q58)*$F58+ N(Q59)*$F59+ N(Q61)*$F61+ N(Q62)*$F62+ N(Q63)*$F63+ N(Q64)*$F64+ N(Q65)*$F65+ N(Q67)*$F67+ N(Q68)*$F68)/ (IF(Q5="N/A",0,$F5*5)+ IF(Q6="N/A",0,$F6*5)+ IF(Q7="N/A",0,$F7*5)+ IF(Q8="N/A",0,$F8*5)+ IF(Q10="N/A",0,$F10*5)+ IF(Q11="N/A",0,$F11*5)+ IF(Q12="N/A",0,$F12*5)+ IF(Q13="N/A",0,$F13*5)+ IF(Q15="N/A",0,$F15*5)+ IF(Q16="N/A",0,$F16*5)+ IF(Q17="N/A",0,$F17*5)+ IF(Q18="N/A",0,$F18*5)+ IF(Q19="N/A",0,$F19*5)+ IF(Q20="N/A",0,$F20*5)+ IF(Q21="N/A",0,$F21*5)+ IF(Q23="N/A",0,$F23*5)+ IF(Q24="N/A",0,$F24*5)+ IF(Q25="N/A",0,$F25*5)+ IF(Q27="N/A",0,$F27*5)+ IF(Q28="N/A",0,$F28*5)+ IF(Q29="N/A",0,$F29*5)+ IF(Q30="N/A",0,$F30*5)+ IF(Q31="N/A",0,$F31*5)+ IF(Q32="N/A",0,$F32*5)+ IF(Q34="N/A",0,$F34*5)+ IF(Q35="N/A",0,$F35*5)+ IF(Q37="N/A",0,$F37*5)+ IF(Q38="N/A",0,$F38*5)+ IF(Q39="N/A",0,$F39*5)+ IF(Q41="N/A",0,$F41*5)+ IF(Q42="N/A",0,$F42*5)+ IF(Q43="N/A",0,$F43*5)+ IF(Q44="N/A",0,$F44*5)+ IF(Q45="N/A",0,$F45*5)+ IF(Q46="N/A",0,$F46*5)+ IF(Q47="N/A",0,$F47*5)+ IF(Q48="N/A",0,$F48*5)+ IF(Q50="N/A",0,$F50*5)+ IF(Q51="N/A",0,$F51*5)+ IF(Q52="N/A",0,$F52*5)++ IF(Q54="N/A",0,$F54*5)+ IF(Q55="N/A",0,$F55*5)+ IF(Q56="N/A",0,$F56*5)+ IF(Q58="N/A",0,$F58*5)+ IF(Q59="N/A",0,$F59*5)+ IF(Q61="N/A",0,$F61*5)+ IF(Q62="N/A",0,$F62*5)+ IF(Q63="N/A",0,$F63*5)+ IF(Q64="N/A",0,$F64*5)+ IF(Q65="N/A",0,$F65*5)+ IF(Q67="N/A",0,$F67*5)+ IF(Q68="N/A",0,$F68*5)))) -> #DIV/0! | R3: =IF(COUNTBLANK(R4:R68)>0,"-", IF(AND(R4="N/A",R9="N/A",R14="N/A",R22="N/A",R26="N/A",R33="N/A",R36="N/A",R40="N/A",R49="N/A",R53="N/A",R57="N/A",R60="N/A",R66="N/A"),"N/A", (N(R5)*$F5+ N(R6)*$F6+ N(R7)*$F7+ N(R8)*$F8+ N(R10)*$F10+ N(R11)*$F11+ N(R12)*$F12+ N(R13)*$F13+ N(R15)*$F15+ N(R16)*$F16+ N(R17)*$F17+ N(R18)*$F18+ N(R19)*$F19+ N(R20)*$F20+ N(R21)*$F21+ N(R23)*$F23+ N(R24)*$F24+ N(R25)*$F25+ N(R27)*$F27+ N(R28)*$F28+ N(R29)*$F29+ N(R30)*$F30+ N(R31)*$F31+ N(R32)*$F32+ N(R34)*$F34+ N(R35)*$F35+ N(R37)*$F37+ N(R38)*$F38+ N(R39)*$F39+ N(R41)*$F41+ N(R42)*$F42+ N(R43)*$F43+ N(R44)*$F44+ N(R45)*$F45+ N(R46)*$F46+ N(R47)*$F47+ N(R48)*$F48+ N(R50)*$F50+ N(R51)*$F51+ N(R51)*$F52+ N(R54)*$F54+ N(R55)*$F55+ N(R56)*$F56+ N(R58)*$F58+ N(R59)*$F59+ N(R61)*$F61+ N(R62)*$F62+ N(R63)*$F63+ N(R64)*$F64+ N(R65)*$F65+ N(R67)*$F67+ N(R68)*$F68)/ (IF(R5="N/A",0,$F5*5)+ IF(R6="N/A",0,$F6*5)+ IF(R7="N/A",0,$F7*5)+ IF(R8="N/A",0,$F8*5)+ IF(R10="N/A",0,$F10*5)+ IF(R11="N/A",0,$F11*5)+ IF(R12="N/A",0,$F12*5)+ IF(R13="N/A",0,$F13*5)+ IF(R15="N/A",0,$F15*5)+ IF(R16="N/A",0,$F16*5)+ IF(R17="N/A",0,$F17*5)+ IF(R18="N/A",0,$F18*5)+ IF(R19="N/A",0,$F19*5)+ IF(R20="N/A",0,$F20*5)+ IF(R21="N/A",0,$F21*5)+ IF(R23="N/A",0,$F23*5)+ IF(R24="N/A",0,$F24*5)+ IF(R25="N/A",0,$F25*5)+ IF(R27="N/A",0,$F27*5)+ IF(R28="N/A",0,$F28*5)+ IF(R29="N/A",0,$F29*5)+ IF(R30="N/A",0,$F30*5)+ IF(R31="N/A",0,$F31*5)+ IF(R32="N/A",0,$F32*5)+ IF(R34="N/A",0,$F34*5)+ IF(R35="N/A",0,$F35*5)+ IF(R37="N/A",0,$F37*5)+ IF(R38="N/A",0,$F38*5)+ IF(R39="N/A",0,$F39*5)+ IF(R41="N/A",0,$F41*5)+ IF(R42="N/A",0,$F42*5)+ IF(R43="N/A",0,$F43*5)+ IF(R44="N/A",0,$F44*5)+ IF(R45="N/A",0,$F45*5)+ IF(R46="N/A",0,$F46*5)+ IF(R47="N/A",0,$F47*5)+ IF(R48="N/A",0,$F48*5)+ IF(R50="N/A",0,$F50*5)+ IF(R51="N/A",0,$F51*5)+ IF(R52="N/A",0,$F52*5)++ IF(R54="N/A",0,$F54*5)+ IF(R55="N/A",0,$F55*5)+ IF(R56="N/A",0,$F56*5)+ IF(R58="N/A",0,$F58*5)+ IF(R59="N/A",0,$F59*5)+ IF(R61="N/A",0,$F61*5)+ IF(R62="N/A",0,$F62*5)+ IF(R63="N/A",0,$F63*5)+ IF(R64="N/A",0,$F64*5)+ IF(R65="N/A",0,$F65*5)+ IF(R67="N/A",0,$F67*5)+ IF(R68="N/A",0,$F68*5)))) -> 0
B4: SIF Y GESTIÓN DE INCIDENTES | L4: =IF(COUNTIF(L5:L8,"=N/A")=4,"N/A", ((N(L5)*$F5)+(N(L6)*$F6)+(N(L7)*$F7)+(N(L8)*$F8))/(IF(L5="N/A",0,(5*$F5))+IF(L6="N/A",0,(5*$F6))+IF(L7="N/A",0,(5*$F7))+IF(L8="N/A",0,(5*$F8)))) -> 0 | M4: =IF(COUNTIF(M5:M8,"=N/A")=4,"N/A", ((N(M5)*$F5)+(N(M6)*$F6)+(N(M7)*$F7)+(N(M8)*$F8))/(IF(M5="N/A",0,(5*$F5))+IF(M6="N/A",0,(5*$F6))+IF(M7="N/A",0,(5*$F7))+IF(M8="N/A",0,(5*$F8)))) -> 0 | N4: =IF(COUNTIF(N5:N8,"=N/A")=4,"N/A", ((N(N5)*$F5)+(N(N6)*$F6)+(N(N7)*$F7)+(N(N8)*$F8))/(IF(N5="N/A",0,(5*$F5))+IF(N6="N/A",0,(5*$F6))+IF(N7="N/A",0,(5*$F7))+IF(N8="N/A",0,(5*$F8)))) -> N/A | O4: =IF(COUNTIF(O5:O8,"=N/A")=4,"N/A", ((N(O5)*$F5)+(N(O6)*$F6)+(N(O7)*$F7)+(N(O8)*$F8))/(IF(O5="N/A",0,(5*$F5))+IF(O6="N/A",0,(5*$F6))+IF(O7="N/A",0,(5*$F7))+IF(O8="N/A",0,(5*$F8)))) -> 0 | P4: =IF(COUNTIF(P5:P8,"=N/A")=4,"N/A", ((N(P5)*$F5)+(N(P6)*$F6)+(N(P7)*$F7)+(N(P8)*$F8))/(IF(P5="N/A",0,(5*$F5))+IF(P6="N/A",0,(5*$F6))+IF(P7="N/A",0,(5*$F7))+IF(P8="N/A",0,(5*$F8)))) -> 0 | Q4: =IF(COUNTIF(Q5:Q8,"=N/A")=4,"N/A", ((N(Q5)*$F5)+(N(Q6)*$F6)+(N(Q7)*$F7)+(N(Q8)*$F8))/(IF(Q5="N/A",0,(5*$F5))+IF(Q6="N/A",0,(5*$F6))+IF(Q7="N/A",0,(5*$F7))+IF(Q8="N/A",0,(5*$F8)))) -> N/A | R4: =IF(COUNTIF(R5:R8,"=N/A")=4,"N/A", ((N(R5)*$F5)+(N(R6)*$F6)+(N(R7)*$F7)+(N(R8)*$F8))/(IF(R5="N/A",0,(5*$F5))+IF(R6="N/A",0,(5*$F6))+IF(R7="N/A",0,(5*$F7))+IF(R8="N/A",0,(5*$F8)))) -> 0
A5: 7_1_32_102 | B5: SIF Y GESTIÓN DE INCIDENTES | C5: 1.1 | D5: Reporte de incidentes/accidentes | E5: SÍ | F5: 1 | G5: Propósito: Ingresar todos los datos en la herramienta nos permite realizar análisis de datos en varios niveles (distribuidor, región). Asegurar visibilidad y responsabilidad en nuestro rendimiento. Con el fin de reducir incidentes/accidentes, se debe implementar un proceso para registrar el entrenamiento y las condiciones inseguras. Asegurar que en el distribuidor exista un proceso y una herramienta para las condiciones inseguras y los comportamientos seguros/inseguros es fundamental para tener éxito en todas las preguntas de ejecución segura (OWD) que siguen en el pilar. Ejemplos de herramientas para informar sobre condiciones inseguras y comportamientos seguros/inseguros en el distribuidor puede ser un formulario interno. | H5: R1.1.1 - El 100% de los Incidentes/accidentes Registrables Totales se documentan en la Herramienta de Informes. No existen brechas. R1.1.2 - El 100% de los Incidentes de Casi Accidente y Primeros Auxilios se documentan en la Herramienta de Informes de Incidentes. No existen brechas. R1.1.3 - Existe un proceso con una herramienta digital para registrar condiciones inseguras y entrenamiento conductual (seguro/insseguro) para permitir la recopilación de datos y el análisis de tendencias. R1.1.4 - Existe una forma saludable en forma de pirámide de seguridad para el distribuidor. El forms de HSMA debe ser ídem al TRI reportado en los GKPIs mensualmente. | I5: Nivel 5 - Todos los requisitos cumplidos. Nivel 3 - Se cumplen R1.1.1, R1.1.2 y R1.1.3, PERO no se cumple R1.1.4. Nivel 1 - Se cumple R1.1.1 con brechas. Nivel 0 - No se cumple R1.1.1. | J5: 1.-Verificar la herramienta de informes de incidentes en busca de posibles brechas en la notificación. 2.-Revisar el proceso y la herramienta de informes de entrenamiento conductual y condiciones inseguras. 3.-Revisar que los datos en la herramienta de entrenamiento conductual y condiciones inseguras estén registrados. 4.-Revisar la pirámide de seguridad del centro de distribución (Pirámide de Bird) para asegurar que exista una forma saludable de pirámide. | L5: =IF(AND(M5="N/A",N5="N/A"),"N/A",IF(OR(M5="",N5=""),"",SMALL(M5:N5,1))) -> 0 | M5: 0 | N5: N/A | O5: =IF(AND(P5="N/A",Q5="N/A"),"N/A",IF(OR(P5="",Q5=""),"",SMALL(P5:Q5,1))) -> 0 | P5: 0 | Q5: N/A | R5: =IF(OR(L5="",O5=""),"",IF(AND(L5="N/A",O5="N/A"),"N/A",AVERAGE(L5,O5))) -> 0
A6: 7_1_32_103 | B6: SIF Y GESTIÓN DE INCIDENTES | C6: 1.2 | D6: Notificacion de incidentes/accidentes | E6: No | F6: 1 | G6: Propósito: Las notificaciones de 24 horas están destinadas a notificar de inmediato el sitio, región a de los incidentes que se han producido. Esto nos permite responder rápidamente e implementar acciones correctivas en todas las ubicaciones. El intercambio de alertas de seguridad al final de nuestra investigación garantiza que la información completa de un caso se distribuya y que los aprendizajes completos sean posibles en todos nuestros sitios. | H6: R1.2.1 - Notificacion al EDV enviada dentro de las 24 horas para cada LTI, MDI, MTI , FAI, Incidentes y SIF actual y potencial. R1.2.2 - Investigación completa para cada LTI, MDI, MTI , FAI y SIF en Gestión de Incidentes dentro de los 7 días. R1.2.3 - Alerta de seguridad publicada y comunicada para cada incidente, LTI, MDI, MTI, FAI, Incidentes SIF Actual y SIF Potencial dentro de los 7 días. | I6: 5 - Cumplimiento de todos los requisitos para el 100% de los casos aplicables 3 - R1.2.1 y R1.2.2 para el 100% de los casos aplicables pero R1.2.3 para <100% de los casos aplicables 1 - R1.2.1 para el 100% de los casos aplicables pero R1.2.2 para <100% de los casos aplicables 0 - R1.2.1 cumplido para <100% de los casos aplicables | J6: 1. Compruebe para el registro notificación de correo electrónico dentro de las 24 horas. 2. Compruebe la herramienta de gestión de incidentes, asegúrese de que los campos de investigación se han completado. 3. Compruebe la ficha de auditoría para verificar la puntualidad de la investigación y que se cierre en un plazo de 7 días. 4. Comprobar si hay constancia de la alerta de seguridad comunicada por cada SIF actual y SIF potencial. | L6: =IF(AND(M6="N/A",N6="N/A"),"N/A",IF(OR(M6="",N6=""),"",SMALL(M6:N6,1))) -> 0 | M6: 0 | N6: N/A | O6: =IF(AND(P6="N/A",Q6="N/A"),"N/A",IF(OR(P6="",Q6=""),"",SMALL(P6:Q6,1))) -> 0 | P6: 0 | Q6: N/A | R6: =IF(OR(L6="",O6=""),"",IF(AND(L6="N/A",O6="N/A"),"N/A",AVERAGE(L6,O6))) -> 0
A7: 7_1_32_104 | B7: SIF Y GESTIÓN DE INCIDENTES | C7: 1.3 | D7: Investigación de incidentes/accidentes y análisis de causa raíz | E7: No | F7: 1 | G7: Propósito: Debemos identificar una causa raíz para cada incidente para que podamos crear acciones correctivas que prevengan la recurrencia de ese incidente. El análisis de la causa raíz debe realizarse utilizando una metodología de resolución de problemas y las acciones correctivas deben administrarse hasta su finalización. | H7: R1.3.1 - Análisis de causa raíz para cada incidente. R1.3.2 - 5 Por qué u otra herramienta del sistema de gestión documentada para cada investigación. Analizar el historico de los involucrados R1.3.3 - Acciones correctivas - deben ser más de 1 acción correctiva. R1.3.4 - Evidencia de la gestión de la acción correctiva. R1.3.5 - Actualización de la evaluación de riesgos. | I7: 5 - Cumplimiento de todos los requisitos para el 100% de los casos aplicables 3 - R1.3.1, R1.3.2 y R1.3.3 para el 100% de los casos aplicables pero R1.3.4 <100% de los casos aplicables 1 - R1.3.3 para el 100% pero R1.3.2 para <100% de los casos 0 - R1.3.1 o R1.3.3 para <100% de los casos cumplidos | J7: 1. Compruebe la herramienta de notificación de incidentes y revise el análisis de causa raíz (Compruebe si el 5 por qué está documentado y si es de buena calidad). 2. Comprobar el instrumento de notificación de incidentes y revisar las medidas correctivas. Compruebe si hay varias acciones, que se relacionen con la causa raíz y que las acciones son más que simplemente el re-entrenamiento. 3. Comprobar el registro de acciones correctivas para verificar que las medidas se hayan cerrado oportunamente. 4. Comprobar la evaluación de riesgo de las instalaciones y validar su actualización como consecuencia de la causa raiz. | L7: =IF(AND(M7="N/A",N7="N/A"),"N/A",IF(OR(M7="",N7=""),"",SMALL(M7:N7,1))) -> 0 | M7: 0 | N7: N/A | O7: =IF(AND(P7="N/A",Q7="N/A"),"N/A",IF(OR(P7="",Q7=""),"",SMALL(P7:Q7,1))) -> 0 | P7: 0 | Q7: N/A | R7: =IF(OR(L7="",O7=""),"",IF(AND(L7="N/A",O7="N/A"),"N/A",AVERAGE(L7,O7))) -> 0
A8: 7_1_32_105 | B8: SIF Y GESTIÓN DE INCIDENTES | C8: 1.4 | D8: Proceso de revisión de rutina de gestión de incidentes/accidentes | E8: No | F8: 1 | G8: Propósito: Es crucial revisar los incidentes/accidentes individuales que ocurren, los detalles de esos casos, la causa raíz y las acciones individuales. Es igualmente importante analizar las tendencias de lo que está causando los incidentes, qué tipos de lesiones están ocurriendo, etc. Este análisis empoderará al sitio para seleccionar acciones correctivas que tengan el poder de impactar en múltiples lesiones y ayudará al sitio a priorizar qué acciones deben tomarse primero. El cascado de la información tiene que ser 100% presencial en las team room. | H8: R1.4.1 - Los incidentes/accidentes se integran en el proceso de revisión rutinario en todos los niveles (Evidencia de notificación de incidentes en salas de equipo, reuniones de entrega, reuniones de gerencia, etc.). El cascado de la información tiene que ser 100% presencial en las team room. R1.4.2 - Análisis de tendencias de incidentes y datos de causa raíz disponibles. R1.4.3 - Identificación de áreas con carteleras de piramide de seguridad. para mejorar la estrategia de conocimiento de los equipos. | I8: Nivel 5 - Todos los requisitos cumplidos con acciones tomadas y ejecutadas que pueden resolver efectivamente el problema. Nivel 3 - Todos los requisitos cumplidos. Nivel 1 - Se cumplen R1.4.1 y R1.4.2. Nivel 0 - No se cumple R1.4.1. | J8: 1. Verificar si los incidentes se analizan como el primer punto en las reuniones de rutina diaria, en el cambio de turno y en las reuniones semanales, y si se abordan de manera eficaz para impulsar el comportamiento de seguridad, generar conciencia y tomar medidas. 2. Verificar si existe un análisis de tendencias de los incidentes y si se identifican las causas fundamentales. 3. Verificar si se identifican áreas de enfoque estratégico para la instalación. | L8: =IF(AND(M8="N/A",N8="N/A"),"N/A",IF(OR(M8="",N8=""),"",SMALL(M8:N8,1))) -> 0 | M8: 0 | N8: N/A | O8: =IF(AND(P8="N/A",Q8="N/A"),"N/A",IF(OR(P8="",Q8=""),"",SMALL(P8:Q8,1))) -> 0 | P8: 0 | Q8: N/A | R8: =IF(OR(L8="",O8=""),"",IF(AND(L8="N/A",O8="N/A"),"N/A",AVERAGE(L8,O8))) -> 0
B9: GESTIÓN DE PROCESOS DE ALTO RIESGO | L9: =IF(COUNTIF(L10:L13,"=N/A")=4,"N/A", ((N(L10)*$F10)+(N(L11)*$F11)+(N(L12)*$F12)+(N(L13)*$F13))/(IF(L10="N/A",0,(5*$F10))+IF(L11="N/A",0,(5*$F11))+IF(L12="N/A",0,(5*$F12))+IF(L13="N/A",0,(5*$F13)))) -> 0 | M9: =IF(COUNTIF(M10:M13,"=N/A")=4,"N/A", ((N(M10)*$F10)+(N(M11)*$F11)+(N(M12)*$F12)+(N(M13)*$F13))/(IF(M10="N/A",0,(5*$F10))+IF(M11="N/A",0,(5*$F11))+IF(M12="N/A",0,(5*$F12))+IF(M13="N/A",0,(5*$F13)))) -> 0 | N9: =IF(COUNTIF(N10:N13,"=N/A")=4,"N/A", ((N(N10)*$F10)+(N(N11)*$F11)+(N(N12)*$F12)+(N(N13)*$F13))/(IF(N10="N/A",0,(5*$F10))+IF(N11="N/A",0,(5*$F11))+IF(N12="N/A",0,(5*$F12))+IF(N13="N/A",0,(5*$F13)))) -> N/A | O9: =IF(COUNTIF(O10:O13,"=N/A")=4,"N/A", ((N(O10)*$F10)+(N(O11)*$F11)+(N(O12)*$F12)+(N(O13)*$F13))/(IF(O10="N/A",0,(5*$F10))+IF(O11="N/A",0,(5*$F11))+IF(O12="N/A",0,(5*$F12))+IF(O13="N/A",0,(5*$F13)))) -> 0 | P9: =IF(COUNTIF(P10:P13,"=N/A")=4,"N/A", ((N(P10)*$F10)+(N(P11)*$F11)+(N(P12)*$F12)+(N(P13)*$F13))/(IF(P10="N/A",0,(5*$F10))+IF(P11="N/A",0,(5*$F11))+IF(P12="N/A",0,(5*$F12))+IF(P13="N/A",0,(5*$F13)))) -> 0 | Q9: =IF(COUNTIF(Q10:Q13,"=N/A")=4,"N/A", ((N(Q10)*$F10)+(N(Q11)*$F11)+(N(Q12)*$F12)+(N(Q13)*$F13))/(IF(Q10="N/A",0,(5*$F10))+IF(Q11="N/A",0,(5*$F11))+IF(Q12="N/A",0,(5*$F12))+IF(Q13="N/A",0,(5*$F13)))) -> N/A | R9: =IF(COUNTIF(R10:R13,"=N/A")=4,"N/A", ((N(R10)*$F10)+(N(R11)*$F11)+(N(R12)*$F12)+(N(R13)*$F13))/(IF(R10="N/A",0,(5*$F10))+IF(R11="N/A",0,(5*$F11))+IF(R12="N/A",0,(5*$F12))+IF(R13="N/A",0,(5*$F13)))) -> 0
A10: 7_1_33_106 | B10: GESTIÓN DE PROCESOS DE ALTO RIESGO | C10: 2.1 | D10: Control y gestión de entornos con déficit de oxígeno | E10: No | F10: 1 | G10: Documente procedimiento de Gestión de procesos de alto riesgo y la supervisión de entornos con deficiencia de oxígeno. | H10: R2.1.1 - Evaluación del riesgo de la unidad realizada para identificar áreas con déficit de oxígeno. R2.1.2 - Áreas potencialmente deficientes de oxígeno equipadas con sistemas de detección y/o programas de monitoreo y gestión. R2.1.3 - Se han establecido controles para las áreas potencialmente deficientes de oxígeno. R2.1.4 - Cuando se utiliza un sistema de detección, es inspeccionado por los operadores con una intervención rutinaria debidamente documentada. | I10: 5 - Todos los requisitos se cumplen 3 - R 2.1.1, R 2.1.2 y R 2.1.3 cumple pero R2.1.4 no cumple 1 - R2.1.1 y R2.1.2 cumple 0 - R2.1.1 no cumple | J10: 1. Revisar la evaluación de riesgos para ver si se han identificado zonas. 2. Comprobar si existen programas de seguimiento y gestión y un sistema de detección. 3. Compruebe si existen controles en su lugar. 4. Hable con los operadores y pregunte sobre estas áreas y si siguen las rutinas de intervención. | L10: =IF(AND(M10="N/A",N10="N/A"),"N/A",IF(OR(M10="",N10=""),"",SMALL(M10:N10,1))) -> 0 | M10: 0 | N10: N/A | O10: =IF(AND(P10="N/A",Q10="N/A"),"N/A",IF(OR(P10="",Q10=""),"",SMALL(P10:Q10,1))) -> 0 | P10: 0 | Q10: N/A | R10: =IF(OR(L10="",O10=""),"",IF(AND(L10="N/A",O10="N/A"),"N/A",AVERAGE(L10,O10))) -> 0
A11: 7_1_33_107 | B11: GESTIÓN DE PROCESOS DE ALTO RIESGO | C11: 2.2 | D11: Monitoreo y gestión de sistemas de amoníaco | E11: No | F11: 1 | G11: Documente procedimiento de gestión de procesos de alto riesgo y la supervisión y gestión de los sistemas de amoníaco. | H11: R2.2.1 - Evaluación de riesgo de las instalaciones realizada para identificar áreas que utilizan el sistema de amoniaco. R2.2.2 - Instalaciones de amoniaco equipadas con sistemas de detección y/o programas de monitoreo y gestión. R2.2.3 - Existen controles para las áreas que utilizan amoniaco. R2.2.4 - Cuando se utiliza un sistema de detección, es inspeccionado por los operadores con una intervención rutinaria debidamente documentada. | I11: 5 - Todos los requisitos cumplieron 3 - R2.2.1, R2.2.2 y R2.2.3 cumplieron pero R2.2.4 no cumplió 1 - R2.2.1 y R2.2.2 cumplió 0 - R2.2.1 no cumplió | J11: 1. Examinar la evaluación de riesgo para ver si se han identificado zonas que utilizan amoniaco. 2. Compruebe si existe un programa de seguimiento y gestión y un sistema de detección. 3. Compruebe si existen controles. 4. Hable con los operadores y pregunte sobre estas áreas y si siguen las rutinas de intervención. | L11: =IF(AND(M11="N/A",N11="N/A"),"N/A",IF(OR(M11="",N11=""),"",SMALL(M11:N11,1))) -> 0 | M11: 0 | N11: N/A | O11: =IF(AND(P11="N/A",Q11="N/A"),"N/A",IF(OR(P11="",Q11=""),"",SMALL(P11:Q11,1))) -> 0 | P11: 0 | Q11: N/A | R11: =IF(OR(L11="",O11=""),"",IF(AND(L11="N/A",O11="N/A"),"N/A",AVERAGE(L11,O11))) -> 0
A12: 7_1_33_108 | B12: GESTIÓN DE PROCESOS DE ALTO RIESGO | C12: 2.3 | D12: Monitoreo y gestión de prevención de explosiones | E12: No | F12: 1 | G12: Identificar áreas con potencial riesgo de explosión, dichas áreas deben estar equipadas con sistema de protección y detección de explosiones dentro del distribuidor. (aplicable para GLP, Diesel, equipos eléctricos, baterias de litio, aceites, grasas y/o lubricantes) | H12: R2.3.1 - Evaluación de riesgo de la instalación realizada para identificar áreas con potencial riesgo de explosión. Se realizo carga de fuego que cubra todas áreas del distribuidor R2.3.2 - Áreas con potencial de explosión equipadas con sistema de detección y/o programas de monitoreo y gestión. R2.3.3 - Los controles están disponibles para áreas con potencial de explosión. R2.3.4 - Cuando se utiliza un sistema de detección, es inspeccionado por los operadores con una intervención rutinaria debidamente documentada. | I12: 5 - Todos los requisitos cumplieron 3 - R2.3.1, R2.3.2 y R2.3.3 se cumplieron pero R2.3.4 no se cumplieron 1 - R2.3.1 y R2.3.2 no se cumplieron 0 - R2.3.1 no se cumplieron | J12: 1. Revisar la evaluación de riesgo para comprobar si se han identificado zonas con potencial de explosión. 2. Compruebe si existe un programa de seguimiento y gestión y un sistema de detección. 3. Compruebe si existen controles. 4. Hable con los operadores y pregunte sobre estas áreas y si siguen las rutinas de intervención. | L12: =IF(AND(M12="N/A",N12="N/A"),"N/A",IF(OR(M12="",N12=""),"",SMALL(M12:N12,1))) -> 0 | M12: 0 | N12: N/A | O12: =IF(AND(P12="N/A",Q12="N/A"),"N/A",IF(OR(P12="",Q12=""),"",SMALL(P12:Q12,1))) -> 0 | P12: 0 | Q12: N/A | R12: =IF(OR(L12="",O12=""),"",IF(AND(L12="N/A",O12="N/A"),"N/A",AVERAGE(L12,O12))) -> 0
A13: 7_1_33_109 | B13: GESTIÓN DE PROCESOS DE ALTO RIESGO | C13: 2.4 | D13: Gestión de sistemas eléctricos | E13: SÍ | F13: 1 | G13: Documente gestión de sistemas eléctricos. | H13: R2.4.1 - No se observaron violaciones eléctricas - Sistemas/equipos eléctricos mantenidos en buenas condiciones y seguros. Plan de acción por el analisis de puesta a tierra, deben mirar las conclusiones identificadas en los resultados. R2.4.2 - Permisos de trabajo eléctrico completados. R2.4.3 - Todos los trabajos eléctricos completados por un empleado calificado propio o externo. | I13: 5 - Todos los requisitos se cumplieron sin violaciones 3 - R2.4.3 cumplió y 1 violación de R2.4.1 o R2.4.2 1 - R2.4.3 cumplió y 2-3 violaciones totales de R2.4.1 o R2.4.2 0 - R2.4.3 no cumplió o >3 violaciones totales de R2.4.1 o R2.4.2 | J13: 1. Revisar las instalaciones y comprobar el estado de los sistemas/equipos eléctricos (conductos eléctricos, tapas de salida faltantes, cubiertas de paneles no aseguradas, cableado expuesto, etc). 2. Revisar los permisos de trabajo y los proyectos, comprobar si se ha completado. 3. Comprobar si hay trabajos eléctricos realizados por trabajadores no cualificados. | L13: =IF(AND(M13="N/A",N13="N/A"),"N/A",IF(OR(M13="",N13=""),"",SMALL(M13:N13,1))) -> 0 | M13: 0 | N13: N/A | O13: =IF(AND(P13="N/A",Q13="N/A"),"N/A",IF(OR(P13="",Q13=""),"",SMALL(P13:Q13,1))) -> 0 | P13: 0 | Q13: N/A | R13: =IF(OR(L13="",O13=""),"",IF(AND(L13="N/A",O13="N/A"),"N/A",AVERAGE(L13,O13))) -> 0
B14: SEGURIDAD EN EL TRANSPORTE EN EL LUGAR DE TRABAJO | L14: =IF(COUNTIF(L15:L18,"=N/A")=4,"N/A", ((N(L15)*$F15)+(N(L16)*$F16)+(N(L17)*$F17)+(N(L18)*$F18))/(IF(L15="N/A",0,(5*$F15))+IF(L16="N/A",0,(5*$F16))+IF(L17="N/A",0,(5*$F17))+IF(L18="N/A",0,(5*$F18)))) -> 0 | M14: =IF(COUNTIF(M15:M21,"=N/A")=4,"N/A", ((N(M15)*$F15)+(N(M16)*$F16)+(N(M17)*$F17)+(N(M18)*$F18)+(N(M19)*$F19)+(N(M20)*$F20)+(N(M21)*$F21))/(IF(M15="N/A",0,(5*$F15))+IF(M16="N/A",0,(5*$F16))+IF(M17="N/A",0,(5*$F17))+IF(M18="N/A",0,(5*$F18))+IF(M19="N/A",0,(5*$F19))+IF(M20="N/A",0,(5*$F20))+IF(M21="N/A",0,(5*$F21)))) -> 0 | N14: =IF(COUNTIF(N15:N21,"=N/A")=4,"N/A", ((N(N15)*$F15)+(N(N16)*$F16)+(N(N17)*$F17)+(N(N18)*$F18)+(N(N19)*$F19)+(N(N20)*$F20)+(N(N21)*$F21))/(IF(N15="N/A",0,(5*$F15))+IF(N16="N/A",0,(5*$F16))+IF(N17="N/A",0,(5*$F17))+IF(N18="N/A",0,(5*$F18))+IF(N19="N/A",0,(5*$F19))+IF(N20="N/A",0,(5*$F20))+IF(N21="N/A",0,(5*$F21)))) -> #DIV/0! | O14: =IF(COUNTIF(O15:O21,"=N/A")=4,"N/A", ((N(O15)*$F15)+(N(O16)*$F16)+(N(O17)*$F17)+(N(O18)*$F18)+(N(O19)*$F19)+(N(O20)*$F20)+(N(O21)*$F21))/(IF(O15="N/A",0,(5*$F15))+IF(O16="N/A",0,(5*$F16))+IF(O17="N/A",0,(5*$F17))+IF(O18="N/A",0,(5*$F18))+IF(O19="N/A",0,(5*$F19))+IF(O20="N/A",0,(5*$F20))+IF(O21="N/A",0,(5*$F21)))) -> 0 | P14: =IF(COUNTIF(P15:P21,"=N/A")=4,"N/A", ((N(P15)*$F15)+(N(P16)*$F16)+(N(P17)*$F17)+(N(P18)*$F18)+(N(P19)*$F19)+(N(P20)*$F20)+(N(P21)*$F21))/(IF(P15="N/A",0,(5*$F15))+IF(P16="N/A",0,(5*$F16))+IF(P17="N/A",0,(5*$F17))+IF(P18="N/A",0,(5*$F18))+IF(P19="N/A",0,(5*$F19))+IF(P20="N/A",0,(5*$F20))+IF(P21="N/A",0,(5*$F21)))) -> 0 | Q14: =IF(COUNTIF(Q15:Q21,"=N/A")=4,"N/A", ((N(Q15)*$F15)+(N(Q16)*$F16)+(N(Q17)*$F17)+(N(Q18)*$F18)+(N(Q19)*$F19)+(N(Q20)*$F20)+(N(Q21)*$F21))/(IF(Q15="N/A",0,(5*$F15))+IF(Q16="N/A",0,(5*$F16))+IF(Q17="N/A",0,(5*$F17))+IF(Q18="N/A",0,(5*$F18))+IF(Q19="N/A",0,(5*$F19))+IF(Q20="N/A",0,(5*$F20))+IF(Q21="N/A",0,(5*$F21)))) -> #DIV/0! | R14: =IF(COUNTIF(R15:R21,"=N/A")=4,"N/A", ((N(R15)*$F15)+(N(R16)*$F16)+(N(R17)*$F17)+(N(R18)*$F18)+(N(R19)*$F19)+(N(R20)*$F20)+(N(R21)*$F21))/(IF(R15="N/A",0,(5*$F15))+IF(R16="N/A",0,(5*$F16))+IF(R17="N/A",0,(5*$F17))+IF(R18="N/A",0,(5*$F18))+IF(R19="N/A",0,(5*$F19))+IF(R20="N/A",0,(5*$F20))+IF(R21="N/A",0,(5*$F21)))) -> 0
A15: 7_1_34_110 | B15: SEGURIDAD EN EL TRANSPORTE EN EL LUGAR DE TRABAJO | C15: 3.1 | D15: Gestión del plan de tráfico | E15: No | F15: 1 | G15: Finalidad: definir el flujo de tráfico y los controles dentro de las instalaciones y el patio de camiones y comunicarlo visualmente a todos los empleados. El plan de tráfico debe utilizarse como medio visual de resolución de problemas y actualizarse cuando se identifiquen nuevos riesgos.. | H15: R3.1.1 - Plan de tráfico implementado. Circulación clara, apilabilidad correspondiente, sendas perimetrales, reductores de velcidad en portones. R3.1.2 - Layout con el plan de tráfico publicado en un área accesible. R3.1.3 - Operadores conscientes del plan de tráfico. R3.1.4 - Señalización suficiente de las normas de seguridad descritas en el plan de tráfico. Identificar zonas habilitadas para fumadores en caso de aplicar. R3.1.5 - Zona Cero al momento del ingreso al almacén, el mismo debe contar con carteleras acerca del layout y debe ser presentado por la operación al momento de una inducción para el ingreso de visitas, auditorias. (Cruzar con almacén) | I15: 5 - Todos los requisitos cumplen 3 - R3.1.1, R3.1.2 y R3.1.4 cumplen 1 - R3.1.1 y R3.1.2 cumplen 0 - R3.1.1 no cumplen | J15: 1. Revise el plan de tráfico establecido por el sitio. 2. Compruebe si el diseño con el plan de tráfico está publicado en áreas donde la gente puede acceder. 3. Hablar con los operadores para asegurarse de que conocen el plan y pueden consultar los detalles del mismo. 4. Compruebe si hay señalización suficiente para cumplir las normas de seguridad establecidas en el plan general de tráfico. | L15: =IF(AND(M15="N/A",N15="N/A"),"N/A",IF(OR(M15="",N15=""),"",SMALL(M15:N15,1))) -> 0 | M15: 0 | N15: N/A | O15: =IF(AND(P15="N/A",Q15="N/A"),"N/A",IF(OR(P15="",Q15=""),"",SMALL(P15:Q15,1))) -> 0 | P15: 0 | Q15: N/A | R15: =IF(OR(L15="",O15=""),"",IF(AND(L15="N/A",O15="N/A"),"N/A",AVERAGE(L15,O15))) -> 0
A16: 7_1_34_111 | B16: SEGURIDAD EN EL TRANSPORTE EN EL LUGAR DE TRABAJO | C16: 3.2 | D16: Carga y descarga de forma segura | E16: No | F16: 1 | G16: Propósito: Un proceso escrito para la carga y descarga debe estar disponible para los empleados. La adhesión a este proceso debe mantenerse a través de nuestras rutinas de Observación del Trabajo Diario (OWD) y sesiones de entrenamiento. Un control que impide físicamente que el vehículo pueda moverse es el estilo de control más robusto. Un candado gladhand es un control simple y económico que impide físicamente que un camión se mueva durante la carga o descarga. | H16: R3.2.1 - Procedimiento de carga/descarga escrito, completo y disponible para los empleados. Dentro del procedimiento, se deben identificar la zona segura del chofer y se debe cumplor 100% (debe contar con segregación) R3.2.2 - Proceso de carga/descarga bien ejecutado (Los neumáticos están bloqueados/asegurados por trabaruedas que son colocados por autoelevadores, las llaves están controladas, los operadores de vehículos están libres de interacción y los operadores de autoelevadores son dueños del proceso). R3.2.3 - Los operadores de autoelevadores controlan completamente la operación de carga/descarga. R3.2.4 - Entrenamiento completo para asegurar que los operadores lleven a cabo la carga/descarga respetando el procedimiento. R3.2.5 - La dirección lleva a cabo los procedimientos de carga/descarga. | I16: 5 - Se cumplieron todos los requisitos y mejoró la tendencia en resultados de coaching/OWD 3 - Todos los requisitos se cumplieron pero los resultados de coaching/OWD no mostraron tendencia de mejora 1 - R3.2.1 y R3.2.3 se cumplieron pero R3.2.2 no se cumplió (un potencial SIF o SIF Actual relacionado con R3.2.2) 0 - R3.1 o R3.3 no se cumplió | J16: 1. Revisar el proceso de carga/descarga: comprobar si está documentado en un SOP. 2. Observe el proceso de carga/descarga: compruebe si el proceso se ejecuta como está documentado (compruebe si el camión está asegurado mediante trabaruedas y control de llave). 3. Compruebe si existe la posibilidad de que el camión se mueva y que el conductor del camión o el conductor del autoelevador resulten heridos. 4. Compruebe la Gestión de Incidentes: ¿ha habido un Potencial SIF o SIF Actual relacionado con reglas de operación seguras que no se siguen? 5. Compruebe el registro de entrenamiento de la instalación - compruebe si hay entrenamiento en la carga/ descarga (positivo y correctivo). 6. Comprobar las OWD de la instalación - comprobar si se están realizando diagnósticos sobre los procedimientos de carga/descarga. | L16: =IF(AND(M16="N/A",N16="N/A"),"N/A",IF(OR(M16="",N16=""),"",SMALL(M16:N16,1))) -> 0 | M16: 0 | N16: N/A | O16: =IF(AND(P16="N/A",Q16="N/A"),"N/A",IF(OR(P16="",Q16=""),"",SMALL(P16:Q16,1))) -> 0 | P16: 0 | Q16: N/A | R16: =IF(OR(L16="",O16=""),"",IF(AND(L16="N/A",O16="N/A"),"N/A",AVERAGE(L16,O16))) -> 0
